Workbook

Sheet Dado Bruto
A2: 1 | B2: -> | D2: E91 | E2: 1.5264 | F2: 1.0866 | G2: E92 | H2: 0 | I2: 0
A3: =A2+1 -> 2 | B3: -> | D3: E1 | E3: I1 | F3: e | G3: E0 | H3: Terra
A4: =A3+1 -> 3 | B4: -> | D4: E0 | E4: 0.1079 | F4: 0.0984 | G4: E1 | H4: 1.0379 | I4: 0.8064 | J4: E2 | K4: 0.2812 | L4: 0.247 | M4: E3 | N4: 0.7971 | O4: 0.5988 | P4: E4 | Q4: 0.2839 | R4: 0.2535 | S4: E5 | T4: 0.7933 | U4: 0.5959 | V4: E6 | W4: 0.2837 | X4: 0.2438 | Y4: E7 | Z4: 0.7922 | AA4: 0.5954 | AB4: 0.7
A5: =A4+1 -> 4 | B5: -> | D5: E2 | E5: I1 | F5: e | G5: E1 | H5: Terra
A6: =A5+1 -> 5 | B6: -> | D6: E0 | E6: 0.879 | F6: 0.6562 | G6: E1 | H6: 0.1083 | I6: 0.0949 | J6: E2 | K6: 0.9499 | L6: 0.7213 | M6: E3 | N6: 0.3684 | O6: 0.3206 | P6: E4 | Q6: 0.8845 | R6: 0.6592 | S6: E5 | T6: 0.3699 | U6: 0.3274 | V6: E6 | W6: 0.8736 | X6: 0.6356 | Y6: E7 | Z6: 0.372 | AA6: 0.3263 | AB6: 0.3449
A7: =A6+1 -> 6 | B7: -> | D7: E3 | E7: I1 | F7: e | G7: E2 | H7: Terra
A8: =A7+1 -> 7 | B8: -> | D8: E0 | E8: 0.182 | F8: 0.1653 | G8: E1 | H8: 0.6994 | I8: 0.5305 | J8: E2 | K8: 0.1101 | L8: 0.0982 | M8: E3 | N8: 0.8185 | O8: 0.6357 | P8: E4 | Q8: 0.1858 | R8: 0.1727 | S8: E5 | T8: 0.6951 | U8: 0.527 | V8: E6 | W8: 0.1874 | X8: 0.1629 | Y8: E7 | Z8: 0.6959 | AA8: 0.5208 | AB8: 0.6287
A9: =A8+1 -> 8 | B9: -> | D9: E4 | E9: I1 | F9: e | G9: E3 | H9: Terra
A10: =A9+1 -> 9 | B10: -> | D10: E0 | E10: 0.753 | F10: 0.5763 | G10: E1 | H10: 0.2337 | I10: 0.2024 | J10: E2 | K10: 0.7412 | L10: 0.5508 | M10: E3 | N10: 0.1047 | O10: 0.091 | P10: E4 | Q10: 0.8823 | R10: 0.6719 | S10: E5 | T10: 0.2332 | U10: 0.2061 | V10: E6 | W10: 0.7421 | X10: 0.5516 | Y10: E7 | Z10: 0.2316 | AA10: 0.2185 | AB10: 0.2172
A11: =A10+1 -> 10 | B11: -> | D11: E5 | E11: I1 | F11: e | G11: E4 | H11: Terra
A12: =A11+1 -> 11 | B12: -> | D12: E0 | E12: 0.2442 | F12: 0.2204 | G12: E1 | H12: 0.7491 | I12: 0.5768 | J12: E2 | K12: 0.2436 | L12: 0.2139 | M12: E3 | N12: 0.7589 | O12: 0.5701 | P12: E4 | Q12: 0.1076 | R12: 0.0943 | S12: E5 | T12: 0.9839 | U12: 0.7657 | V12: E6 | W12: 0.2451 | X12: 0.2202 | Y12: E7 | Z12: 0.7565 | AA12: 0.5669 | AB12: 0.6787
A13: =A12+1 -> 12 | B13: -> | D13: E6 | E13: I1 | F13: e | G13: E5 | H13: Terra
A14: =A13+1 -> 13 | B14: -> | D14: E0 | E14: 0.8567 | F14: 0.6436 | G14: E1 | H14: 0.345 | I14: 0.3043 | J14: E2 | K14: 0.8549 | L14: 0.6414 | M14: E3 | N14: 0.3462 | O14: 0.3036 | P14: E4 | Q14: 0.8564 | R14: 0.6433 | S14: E5 | T14: 0.1042 | U14: 0.0901 | V14: E6 | W14: 0.9156 | X14: 0.6937 | Y14: E7 | Z14: 0.3458 | AA14: 0.3122 | AB14: 0.3222
A15: =A14+1 -> 14 | B15: -> | D15: E7 | E15: I1 | F15: e | G15: E6 | H15: Terra
A16: =A15+1 -> 15 | B16: -> | D16: E0 | E16: 0.1713 | F16: 0.1623 | G16: E1 | H16: 0.682 | I16: 0.5044 | J16: E2 | K16: 0.1679 | L16: 0.1498 | M16: E3 | N16: 0.6823 | O16: 0.5064 | P16: E4 | Q16: 0.1697 | R16: 0.1526 | S16: E5 | T16: 0.6797 | U16: 0.5016 | V16: E6 | W16: 0.1055 | X16: 0.0932 | Y16: E7 | Z16: 1.018 | AA16: 0.7902 | AB16: 0.8674
A17: =A16+1 -> 16 | B17: -> | D17: E0 | E17: I1 | F17: e | G17: E7 | H17: Terra
A18: =A17+1 -> 17 | B18: -> | D18: E0 | E18: 1.0814 | F18: 0.7956 | G18: E1 | H18: 0.4504 | I18: 0.3746 | J18: E2 | K18: 0.9419 | L18: 0.6982 | M18: E3 | N18: 0.4518 | O18: 0.393 | P18: E4 | Q18: 0.9466 | R18: 0.7178 | S18: E5 | T18: 0.4487 | U18: 0.3874 | V18: E6 | W18: 0.9511 | X18: 0.7056 | Y18: E7 | Z18: 0.105 | AA18: 0.092 | AB18: 0.0953
A19: =A18+1 -> 18
A20: =A19+1 -> 19
A21: =A20+1 -> 20
A22: =A21+1 -> 21 | B22: -> | D22: E91 | E22: 1.5277 | F22: 1.0574 | G22: E92 | H22: 0 | I22: 0
A23: =A22+1 -> 22 | B23: -> | D23: E1 | E23: I1 | F23: e | G23: E0 | H23: Terra
A24: =A23+1 -> 23 | B24: -> | D24: E0 | E24: 0.1072 | F24: 0.0936 | G24: E1 | H24: 1.0344 | I24: 0.7984 | J24: E2 | K24: 0.2805 | L24: 0.2466 | M24: E3 | N24: 0.7957 | O24: 0.599 | P24: E4 | Q24: 0.2834 | R24: 0.2494 | S24: E5 | T24: 0.7926 | U24: 0.5971 | V24: E6 | W24: 0.2828 | X24: 0.2497 | Y24: E7 | Z24: 0.7933 | AA24: 0.595
A25: =A24+1 -> 24 | B25: -> | D25: E2 | E25: I1 | F25: e | G25: E1 | H25: Terra
A26: =A25+1 -> 25 | B26: -> | D26: E0 | E26: 0.8731 | F26: 0.6404 | G26: E1 | H26: 0.1058 | I26: 0.0944 | J26: E2 | K26: 0.945 | L26: 0.6995 | M26: E3 | N26: 0.3733 | O26: 0.3192 | P26: E4 | Q26: 0.8728 | R26: 0.6538 | S26: E5 | T26: 0.3686 | U26: 0.3257 | V26: E6 | W26: 0.875 | X26: 0.6702 | Y26: E7 | Z26: 0.3627 | AA26: 0.342
A27: =A26+1 -> 26 | B27: -> | D27: E3 | E27: I1 | F27: e | G27: E2 | H27: Terra | AB27: 0.6953
A28: =A27+1 -> 27 | B28: -> | D28: E0 | E28: 0.1877 | F28: 0.1776 | G28: E1 | H28: 0.697 | I28: 0.5303 | J28: E2 | K28: 0.1108 | L28: 0.1005 | M28: E3 | N28: 0.8224 | O28: 0.6234 | P28: E4 | Q28: 0.1873 | R28: 0.1704 | S28: E5 | T28: 0.6958 | U28: 0.5279 | V28: E6 | W28: 0.1859 | X28: 0.1721 | Y28: E7 | Z28: 0.697 | AA28: 0.5267
A29: =A28+1 -> 28 | B29: -> | D29: E4 | E29: I1 | F29: e | G29: E3 | H29: Terra | AB29: 0.3483
A30: =A29+1 -> 29 | B30: -> | D30: E0 | E30: 0.7424 | F30: 0.5501 | G30: E1 | H30: 0.2349 | I30: 0.2073 | J30: E2 | K30: 0.7437 | L30: 0.5531 | M30: E3 | N30: 0.1088 | O30: 0.0968 | P30: E4 | Q30: 0.886 | R30: 0.6705 | S30: E5 | T30: 0.2351 | U30: 0.2043 | V30: E6 | W30: 0.7416 | X30: 0.553 | Y30: E7 | Z30: 0.2339 | AA30: 0.2152
A31: =A30+1 -> 30 | B31: -> | D31: E5 | E31: I1 | F31: e | G31: E4 | H31: Terra | AB31: 0.6106
A32: =A31+1 -> 31 | B32: -> | D32: E0 | E32: 0.2508 | F32: 0.2283 | G32: E1 | H32: 0.7556 | I32: 0.5748 | J32: E2 | K32: 0.2437 | L32: 0.2211 | M32: E3 | N32: 0.7564 | O32: 0.5771 | P32: E4 | Q32: 0.1046 | R32: 0.0907 | S32: E5 | T32: 0.9864 | U32: 0.7732 | V32: E6 | W32: 0.2441 | X32: 0.2194 | Y32: E7 | Z32: 0.7552 | AA32: 0.5668
A33: =A32+1 -> 32 | B33: -> | D33: E6 | E33: I1 | F33: e | G33: E5 | H33: Terra | AB33: 0.2174
A34: =A33+1 -> 33 | B34: -> | D34: E0 | E34: 0.8557 | F34: 0.6358 | G34: E1 | H34: 0.3449 | I34: 0.3013 | J34: E2 | K34: 0.8512 | L34: 0.6394 | M34: E3 | N34: 0.3489 | O34: 0.3118 | P34: E4 | Q34: 0.856 | R34: 0.6437 | S34: E5 | T34: 0.1039 | U34: 0.0919 | V34: E6 | W34: 0.9141 | X34: 0.6922 | Y34: E7 | Z34: 0.3463 | AA34: 0.3116
A35: =A34+1 -> 34 | B35: -> | D35: E7 | E35: I1 | F35: e | G35: E6 | H35: Terra | AB35: 0.6786
A36: =A35+1 -> 35 | B36: -> | D36: E0 | E36: 0.1687 | F36: 0.1622 | G36: E1 | H36: 0.6818 | I36: 0.4981 | J36: E2 | K36: 0.1713 | L36: 0.1526 | M36: E3 | N36: 0.68 | O36: 0.502 | P36: E4 | Q36: 0.1702 | R36: 0.1536 | S36: E5 | T36: 0.6794 | U36: 0.5057 | V36: E6 | W36: 0.1058 | X36: 0.0942 | Y36: E7 | Z36: 1.019 | AA36: 0.7856
A37: =A36+1 -> 36 | B37: -> | D37: E0 | E37: I1 | F37: e | G37: E7 | H37: Terra | AB37: 0.3247
A38: =A37+1 -> 37 | B38: -> | D38: E0 | E38: 1.1013 | F38: 0.7983 | G38: E1 | H38: 0.4561 | I38: 0.3697 | J38: E2 | K38: 0.9565 | L38: 0.6906 | M38: E3 | N38: 0.454 | O38: 0.3747 | P38: E4 | Q38: 0.9654 | R38: 0.6905 | S38: E5 | T38: 0.4523 | U38: 0.3682 | V38: E6 | W38: 0.9579 | X38: 0.6845 | Y38: E7 | Z38: 0.1048 | AA38: 0.084
A39: =A38+1 -> 38
A40: =A39+1 -> 39
A41: =A40+1 -> 40
...

Sheet Dados processados
A1: CORRENTE
B2: {=_xlfn._xlws.FILTER('Dado Bruto'!A:AB, ('Dado Bruto'!A:A=1) + ('Dado Bruto'!A:A=21) + ('Dado Bruto'!A:A=41)+ ('Dado Bruto'!A:A=61)+ ('Dado Bruto'!A:A=81), "Não encontrado")} -> 1 | C2: -> | D2: 0 | E2: E91 | F2: 1.5264 | G2: 1.0866 | H2: E92 | I2: 0 | J2: 0 | K2: 0 | L2: 0 | M2: 0 | N2: 0 | O2: 0 | P2: 0 | Q2: 0 | R2: 0 | S2: 0 | T2: 0 | U2: 0 | V2: 0 | W2: 0 | X2: 0 | Y2: 0 | Z2: 0 | AA2: 0 | AB2: 0 | AC2: 0
B3: 21 | C3: -> | D3: 0 | E3: E91 | F3: 1.5277 | G3: 1.0574 | H3: E92 | I3: 0 | J3: 0 | K3: 0 | L3: 0 | M3: 0 | N3: 0 | O3: 0 | P3: 0 | Q3: 0 | R3: 0 | S3: 0 | T3: 0 | U3: 0 | V3: 0 | W3: 0 | X3: 0 | Y3: 0 | Z3: 0 | AA3: 0 | AB3: 0 | AC3: 0
B4: 41 | C4: -> | D4: 0 | E4: E91 | F4: 1.5607 | G4: 1.0449 | H4: E92 | I4: 0 | J4: 0 | K4: 0 | L4: 0 | M4: 0 | N4: 0 | O4: 0 | P4: 0 | Q4: 0 | R4: 0 | S4: 0 | T4: 0 | U4: 0 | V4: 0 | W4: 0 | X4: 0 | Y4: 0 | Z4: 0 | AA4: 0 | AB4: 0 | AC4: 0.8849
B5: 61 | C5: -> | D5: 0 | E5: E91 | F5: 1.5638 | G5: 1.038 | H5: E92 | I5: 0 | J5: 0 | K5: 0 | L5: 0 | M5: 0 | N5: 0 | O5: 0 | P5: 0 | Q5: 0 | R5: 0 | S5: 0 | T5: 0 | U5: 0 | V5: 0 | W5: 0 | X5: 0 | Y5: 0 | Z5: 0 | AA5: 0 | AB5: 0 | AC5: 0
B6: 81 | C6: -> | D6: 0 | E6: E91 | F6: 1.5324 | G6: 1.0791 | H6: E92 | I6: 0 | J6: 0 | K6: 0 | L6: 0 | M6: 0 | N6: 0 | O6: 0 | P6: 0 | Q6: 0 | R6: 0 | S6: 0 | T6: 0 | U6: 0 | V6: 0 | W6: 0 | X6: 0 | Y6: 0 | Z6: 0 | AA6: 0 | AB6: 0 | AC6: 0.2172
A7: Média | F7: =AVERAGE(F2:F6) -> 1.5422 | G7: =AVERAGE(G2:G6) -> 1.0612
A8: STD | F8: =_xlfn.STDEV.P(F2:F6) -> 0.016521138 | G8: =_xlfn.STDEV.P(G2:G6) -> 0.018888833
A9: SNR (dB) | F9: =20*LOG10(F7/F8) -> 39.402015 | G9: =20*LOG10(G7/G8) -> 34.991842
A10: Valor simulado | F10: =(0.000528)*2*1000 -> 1.056 | G10: =(0.0005259)*2*1000 -> 1.0518
A11: Acurácia | F11: =1- ((+F7-F10)/F10) -> 0.53958333 | G11: =1- ((G7-G10)/G10) -> 0.99106294
A13: E1 conectado ao I1 e E0 conectado ao terra
B14: {=_xlfn._xlws.FILTER('Dado Bruto'!A:AB, ('Dado Bruto'!A:A=3) + ('Dado Bruto'!A:A=23) + ('Dado Bruto'!A:A=43)+ ('Dado Bruto'!A:A=63)+ ('Dado Bruto'!A:A=83), "Não encontrado")} -> 3 | C14: -> | D14: 0 | E14: E0 | F14: 0.1079 | G14: 0.0984 | H14: E1 | I14: 1.0379 | J14: 0.8064 | K14: E2 | L14: 0.2812 | M14: 0.247 | N14: E3 | O14: 0.7971 | P14: 0.5988 | Q14: E4 | R14: 0.2839 | S14: 0.2535 | T14: E5 | U14: 0.7933 | V14: 0.5959 | W14: E6 | X14: 0.2837 | Y14: 0.2438 | Z14: E7 | AA14: 0.7922 | AB14: 0.5954 | AC14: 0.7 | AD14: E2 E4 E6 | AE14: DP | AF14: E2 E4 E6 | AG14: DP | AI14: E3 E5 E7 | AJ14: DP | AK14: E3 E5 E7 | AL14: DP
B15: 23 | C15: -> | D15: 0 | E15: E0 | F15: 0.1072 | G15: 0.0936 | H15: E1 | I15: 1.0344 | J15: 0.7984 | K15: E2 | L15: 0.2805 | M15: 0.2466 | N15: E3 | O15: 0.7957 | P15: 0.599 | Q15: E4 | R15: 0.2834 | S15: 0.2494 | T15: E5 | U15: 0.7926 | V15: 0.5971 | W15: E6 | X15: 0.2828 | Y15: 0.2497 | Z15: E7 | AA15: 0.7933 | AB15: 0.595 | AC15: 0 | AD15: =AVERAGE(L15,R15,X15) -> 0.28223333 | AF15: =AVERAGE(M15,S15,Y15) -> 0.24856667
B16: 43 | C16: -> | D16: 0 | E16: E0 | F16: 0.108 | G16: 0.1032 | H16: E1 | I16: 1.0354 | J16: 0.7988 | K16: E2 | L16: 0.2784 | M16: 0.2488 | N16: E3 | O16: 0.7921 | P16: 0.5963 | Q16: E4 | R16: 0.283 | S16: 0.252 | T16: E5 | U16: 0.793 | V16: 0.6004 | W16: E6 | X16: 0.2832 | Y16: 0.2457 | Z16: E7 | AA16: 0.7928 | AB16: 0.5958 | AC16: 0.0918 | AD16: =AVERAGE(L16,R16,X16) -> 0.28153333 | AF16: =AVERAGE(M16,S16,Y16) -> 0.24883333
B17: 63 | C17: -> | D17: 0 | E17: E0 | F17: 0.1078 | G17: 0.0984 | H17: E1 | I17: 1.0389 | J17: 0.8091 | K17: E2 | L17: 0.2855 | M17: 0.2491 | N17: E3 | O17: 0.7939 | P17: 0.5977 | Q17: E4 | R17: 0.2862 | S17: 0.25 | T17: E5 | U17: 0.7932 | V17: 0.5948 | W17: E6 | X17: 0.2791 | Y17: 0.2451 | Z17: E7 | AA17: 0.7933 | AB17: 0.5959 | AC17: 0 | AD17: =AVERAGE(L17,R17,X17) -> 0.2836 | AF17: =AVERAGE(M17,S17,Y17) -> 0.24806667
B18: 83 | C18: -> | D18: 0 | E18: E0 | F18: 0.1099 | G18: 0.0965 | H18: E1 | I18: 1.0352 | J18: 0.8 | K18: E2 | L18: 0.2823 | M18: 0.2504 | N18: E3 | O18: 0.7939 | P18: 0.5952 | Q18: E4 | R18: 0.2839 | S18: 0.2515 | T18: E5 | U18: 0.7932 | V18: 0.5976 | W18: E6 | X18: 0.2823 | Y18: 0.2499 | Z18: E7 | AA18: 0.7946 | AB18: 0.5968 | AC18: 0.6781 | AD18: =AVERAGE(L18,R18,X18) -> 0.28283333 | AF18: =AVERAGE(M18,S18,Y18) -> 0.2506
A19: Média | F19: =AVERAGE(F14:F18) -> 0.10816 | G19: =AVERAGE(G14:G18) -> 0.09802 | I19: =AVERAGE(I14:I18) -> 1.03636 | J19: =AVERAGE(J14:J18) -> 0.80254 | L19: =AVERAGE(L14:L18) -> 0.28158 | M19: =AVERAGE(M14:M18) -> 0.24838 | O19: =AVERAGE(O14:O18) -> 0.79454 | P19: =AVERAGE(P14:P18) -> 0.5974 | R19: =AVERAGE(R14:R18) -> 0.28408 | S19: =AVERAGE(S14:S18) -> 0.25128 | U19: =AVERAGE(U14:U18) -> 0.79306 | V19: =AVERAGE(V14:V18) -> 0.59716 | X19: =AVERAGE(X14:X18) -> 0.28222 | Y19: =AVERAGE(Y14:Y18) -> 0.24684 | AA19: =AVERAGE(AA14:AA18) -> 0.79324 | AB19: =AVERAGE(AB14:AB18) -> 0.59578 | AD19: =AVERAGE(L19,R19,X19) -> 0.28262667 | AF19: =AVERAGE(M19,S19,Y19) -> 0.24883333
A20: STD | F20: =_xlfn.STDEV.P(F14:F18) -> 0.00091345498 | G20: =_xlfn.STDEV.P(G14:G18) -> 0.0031294728 | I20: =_xlfn.STDEV.P(I14:I18) -> 0.0017281204 | J20: =_xlfn.STDEV.P(J14:J18) -> 0.0043706292 | L20: =_xlfn.STDEV.P(L14:L18) -> 0.0023370066 | M20: =_xlfn.STDEV.P(M14:M18) -> 0.0014034244 | O20: =_xlfn.STDEV.P(O14:O18) -> 0.001713009 | P20: =_xlfn.STDEV.P(P14:P18) -> 0.001460137 | R20: =_xlfn.STDEV.P(R14:R18) -> 0.0011124747 | S20: =_xlfn.STDEV.P(S14:S18) -> 0.0014606848 | U20: =_xlfn.STDEV.P(U14:U18) -> 0.00024979992 | V20: =_xlfn.STDEV.P(V14:V18) -> 0.0018895502 | X20: =_xlfn.STDEV.P(X14:X18) -> 0.00162653 | Y20: =_xlfn.STDEV.P(Y14:Y18) -> 0.0024944739 | AA20: =_xlfn.STDEV.P(AA14:AA18) -> 0.00079145436 | AB20: =_xlfn.STDEV.P(AB14:AB18) -> 0.00060133186
A21: SNR (dB) | F21: =20*LOG10(F19/F20) -> 41.467591 | G21: =20*LOG10(G19/G20) -> 29.91687 | I21: =20*LOG10(I19/I20) -> 55.558733 | J21: =20*LOG10(J19/J20) -> 45.278454 | L21: =20*LOG10(L19/L20) -> 41.618837 | M21: =20*LOG10(M19/M20) -> 44.958552 | O21: =20*LOG10(O19/O20) -> 53.327122 | P21: =20*LOG10(P19/P20) -> 52.237432 | R21: =20*LOG10(R19/R20) -> 48.14301 | S21: =20*LOG10(S19/S20) -> 44.712028 | U21: =20*LOG10(U19/U20) -> 70.034275 | V21: =20*LOG10(V19/V20) -> 49.994645 | X21: =20*LOG10(X19/X20) -> 44.786514 | Y21: =20*LOG10(Y19/Y20) -> 39.908731 | AA21: =20*LOG10(AA19/AA20) -> 60.019575 | AB21: =20*LOG10(AB19/AB20) -> 59.919434 | AC21: =AVERAGE(F21:AB21) -> 48.867613
A22: Valor simulado | F22: 0.132 | G22: 0.1315 | I22: 1.0964 | J22: 0.9857 | L22: 0.3057 | M22: 0.3045 | O22: 0.8293 | P22: 0.7294 | R22: 0.3057 | S22: 0.3045 | U22: 0.8293 | V22: 0.7294 | X22: 0.3057 | Y22: 0.3045 | AA22: 0.8293 | AB22: 0.7294
A23: Acurácia | F23: =1-((F22-F19)/F19) -> 0.7795858 | G23: =1-((G22-G19)/G19) -> 0.65843705 | I23: =1-((I22-I19)/I19) -> 0.94206646 | J23: =1-((+J22-J19)/J19) -> 0.77177462 | L23: =1-((L22-L19)/L19) -> 0.91434051 | M23: =1-((M22-M19)/M19) -> 0.77405588 | O23: =1-((O22-O19)/O19) -> 0.95625142 | P23: =1-((P22-P19)/P19) -> 0.77904252 | R23: =1-((R22-R19)/R19) -> 0.92389468 | S23: =1-((S22-S19)/S19) -> 0.78820439 | U23: =1-((U22-U19)/U19) -> 0.95430358 | V23: =1-((V22-V19)/V19) -> 0.77855181 | X23: =1-((X22-X19)/X19) -> 0.91680249 | Y23: =1-((Y22-Y19)/Y19) -> 0.76640739 | AA23: =1-((AA22-AA19)/AA19) -> 0.95454087 | AB23: =1-((AB22-AB19)/AB19) -> 0.77572258
A25: E2 conectado ao I1 e E1 conectado ao terra
B26: {=_xlfn._xlws.FILTER('Dado Bruto'!A:AB, ('Dado Bruto'!A:A=5) + ('Dado Bruto'!A:A=25) + ('Dado Bruto'!A:A=45)+ ('Dado Bruto'!A:A=65)+ ('Dado Bruto'!A:A=85), "Não encontrado")} -> 5 | C26: -> | D26: 0 | E26: E0 | F26: 0.879 | G26: 0.6562 | H26: E1 | I26: 0.1083 | J26: 0.0949 | K26: E2 | L26: 0.9499 | M26: 0.7213 | N26: E3 | O26: 0.3684 | P26: 0.3206 | Q26: E4 | R26: 0.8845 | S26: 0.6592 | T26: E5 | U26: 0.3699 | V26: 0.3274 | W26: E6 | X26: 0.8736 | Y26: 0.6356 | Z26: E7 | AA26: 0.372 | AB26: 0.3263 | AC26: 0.3449
B27: 25 | C27: -> | D27: 0 | E27: E0 | F27: 0.8731 | G27: 0.6404 | H27: E1 | I27: 0.1058 | J27: 0.0944 | K27: E2 | L27: 0.945 | M27: 0.6995 | N27: E3 | O27: 0.3733 | P27: 0.3192 | Q27: E4 | R27: 0.8728 | S27: 0.6538 | T27: E5 | U27: 0.3686 | V27: 0.3257 | W27: E6 | X27: 0.875 | Y27: 0.6702 | Z27: E7 | AA27: 0.3627 | AB27: 0.342 | AC27: 0
B28: 45 | C28: -> | D28: 0 | E28: E0 | F28: 0.8767 | G28: 0.6467 | H28: E1 | I28: 0.1074 | J28: 0.0949 | K28: E2 | L28: 0.9518 | M28: 0.7227 | N28: E3 | O28: 0.3706 | P28: 0.3211 | Q28: E4 | R28: 0.8792 | S28: 0.6575 | T28: E5 | U28: 0.3681 | V28: 0.319 | W28: E6 | X28: 0.8755 | Y28: 0.6535 | Z28: E7 | AA28: 0.3684 | AB28: 0.3297 | AC28: 0
B29: 65 | C29: -> | D29: 0 | E29: E0 | F29: 0.8772 | G29: 0.6589 | H29: E1 | I29: 0.1073 | J29: 0.0946 | K29: E2 | L29: 0.9529 | M29: 0.72 | N29: E3 | O29: 0.3697 | P29: 0.3203 | Q29: E4 | R29: 0.8809 | S29: 0.6576 | T29: E5 | U29: 0.3668 | V29: 0.3206 | W29: E6 | X29: 0.8776 | Y29: 0.6578 | Z29: E7 | AA29: 0.3699 | AB29: 0.335 | AC29: 0
B30: 85 | C30: -> | D30: 0 | E30: E0 | F30: 0.8793 | G30: 0.6552 | H30: E1 | I30: 0.1082 | J30: 0.0946 | K30: E2 | L30: 0.9527 | M30: 0.7244 | N30: E3 | O30: 0.3695 | P30: 0.3248 | Q30: E4 | R30: 0.8818 | S30: 0.6558 | T30: E5 | U30: 0.3691 | V30: 0.3201 | W30: E6 | X30: 0.8755 | Y30: 0.653 | Z30: E7 | AA30: 0.367 | AB30: 0.3302 | AC30: 0.3235
A31: Média | F31: =AVERAGE(F26:F30) -> 0.87706 | G31: =AVERAGE(G26:G30) -> 0.65148 | I31: =AVERAGE(I26:I30) -> 0.1074 | J31: =AVERAGE(J26:J30) -> 0.09468 | L31: =AVERAGE(L26:L30) -> 0.95046 | M31: =AVERAGE(M26:M30) -> 0.71758 | O31: =AVERAGE(O26:O30) -> 0.3703 | P31: =AVERAGE(P26:P30) -> 0.3212 | R31: =AVERAGE(R26:R30) -> 0.87984 | S31: =AVERAGE(S26:S30) -> 0.65678 | U31: =AVERAGE(U26:U30) -> 0.3685 | V31: =AVERAGE(V26:V30) -> 0.32256 | X31: =AVERAGE(X26:X30) -> 0.87544 | Y31: =AVERAGE(Y26:Y30) -> 0.65402 | AA31: =AVERAGE(AA26:AA30) -> 0.368 | AB31: =AVERAGE(AB26:AB30) -> 0.33264
A32: STD | F32: =_xlfn.STDEV.P(F26:F30) -> 0.0022186482 | G32: =_xlfn.STDEV.P(G26:G30) -> 0.0068816858 | I32: =_xlfn.STDEV.P(I26:I30) -> 0.00089666047 | J32: =_xlfn.STDEV.P(J26:J30) -> 0.00019390719 | L32: =_xlfn.STDEV.P(L26:L30) -> 0.0029288906 | M32: =_xlfn.STDEV.P(M26:M30) -> 0.0091575979 | O32: =_xlfn.STDEV.P(O26:O30) -> 0.0016552945 | P32: =_xlfn.STDEV.P(P26:P30) -> 0.001904731 | R32: =_xlfn.STDEV.P(R26:R30) -> 0.0039154055 | S32: =_xlfn.STDEV.P(S26:S30) -> 0.0018378248 | U32: =_xlfn.STDEV.P(U26:U30) -> 0.0010373042 | V32: =_xlfn.STDEV.P(V26:V30) -> 0.0033422148 | X32: =_xlfn.STDEV.P(X26:X30) -> 0.0012846789 | Y32: =_xlfn.STDEV.P(Y26:Y30) -> 0.011105746 | AA32: =_xlfn.STDEV.P(AA26:AA30) -> 0.0031260198 | AB32: =_xlfn.STDEV.P(AB26:AB30) -> 0.0054400735
A33: SNR (dB) | F33: =20*LOG10(F31/F32) -> 51.938817 | G33: =20*LOG10(G31/G32) -> 39.524125 | I33: =20*LOG10(I31/I32) -> 41.567525 | J33: =20*LOG10(J31/J32) -> 53.773287 | L33: =20*LOG10(L31/L32) -> 50.224614 | M33: =20*LOG10(M31/M32) -> 37.881775 | O33: =20*LOG10(O31/O32) -> 46.993569 | P33: =20*LOG10(P31/P32) -> 44.538838 | R33: =20*LOG10(R31/R32) -> 47.032539 | S33: =20*LOG10(S31/S32) -> 51.062316 | U33: =20*LOG10(U31/U32) -> 51.010627 | V33: =20*LOG10(V31/V32) -> 39.691523 | X33: =20*LOG10(X31/X32) -> 56.668636 | Y33: =20*LOG10(Y31/Y32) -> 35.400866 | AA33: =20*LOG10(AA31/AA32) -> 41.417122 | AB33: =20*LOG10(AB31/AB32) -> 35.727394 | AC33: =AVERAGE(F33:AB33) -> 45.278348
A34: Valor simulado | F34: 0.9229 | G34: 0.8184 | I34: 0.132 | J34: 0.1315 | L34: 0.9984 | M34: 0.8908 | O34: 0.3992 | P34: 0.3976 | R34: 0.9229 | S34: 0.8184 | U34: 0.3992 | V34: 0.3976 | X34: 0.9229 | Y34: 0.8184 | AA34: 0.3992 | AB34: 0.3976
A35: Acurácia | F35: =1-((F34-F31)/F31) -> 0.94773448 | G35: =1-((G34-G31)/G31) -> 0.74378339 | I35: =1-((I34-I31)/I31) -> 0.77094972 | J35: =1-((J34-J31)/J31) -> 0.61111111 | L35: =1-((L34-L31)/L31) -> 0.94956127 | M35: =1-((M34-M31)/M31) -> 0.75860531 | O35: =1-((O34-O31)/O31) -> 0.92195517 | P35: =1-((P34-P31)/P31) -> 0.76214197 | R35: =1-((R34-R31)/R31) -> 0.95105928 | S35: =1-((S34-S31)/S31) -> 0.75392064 | U35: =1-((U34-U31)/U31) -> 0.91668928 | V35: =1-((V34-V31)/V31) -> 0.76736111 | X35: =1-((X34-X31)/X31) -> 0.94578726 | Y35: =1-((Y34-Y31)/Y31) -> 0.74866212 | AA35: =1-((AA34-AA31)/AA31) -> 0.91521739 | AB35: =1-((AB34-AB31)/AB31) -> 0.8047138
A37: E3 conectado ao I1 e E2 conectado ao terra
B38: {=_xlfn._xlws.FILTER('Dado Bruto'!A:AB, ('Dado Bruto'!A:A=7) + ('Dado Bruto'!A:A=27) + ('Dado Bruto'!A:A=47)+ ('Dado Bruto'!A:A=67)+ ('Dado Bruto'!A:A=87), "Não encontrado")} -> 7 | C38: -> | D38: 0 | E38: E0 | F38: 0.182 | G38: 0.1653 | H38: E1 | I38: 0.6994 | J38: 0.5305 | K38: E2 | L38: 0.1101 | M38: 0.0982 | N38: E3 | O38: 0.8185 | P38: 0.6357 | Q38: E4 | R38: 0.1858 | S38: 0.1727 | T38: E5 | U38: 0.6951 | V38: 0.527 | W38: E6 | X38: 0.1874 | Y38: 0.1629 | Z38: E7 | AA38: 0.6959 | AB38: 0.5208 | AC38: 0.6287
B39: 27 | C39: -> | D39: 0 | E39: E0 | F39: 0.1877 | G39: 0.1776 | H39: E1 | I39: 0.697 | J39: 0.5303 | K39: E2 | L39: 0.1108 | M39: 0.1005 | N39: E3 | O39: 0.8224 | P39: 0.6234 | Q39: E4 | R39: 0.1873 | S39: 0.1704 | T39: E5 | U39: 0.6958 | V39: 0.5279 | W39: E6 | X39: 0.1859 | Y39: 0.1721 | Z39: E7 | AA39: 0.697 | AB39: 0.5267 | AC39: 0
B40: 47 | C40: -> | D40: 0 | E40: E0 | F40: 0.1906 | G40: 0.1783 | H40: E1 | I40: 0.6972 | J40: 0.5328 | K40: E2 | L40: 0.1096 | M40: 0.1005 | N40: E3 | O40: 0.8207 | P40: 0.6422 | Q40: E4 | R40: 0.1871 | S40: 0.1716 | T40: E5 | U40: 0.6955 | V40: 0.5307 | W40: E6 | X40: 0.1863 | Y40: 0.1702 | Z40: E7 | AA40: 0.6969 | AB40: 0.5235 | AC40: 0
B41: 67 | C41: -> | D41: 0 | E41: E0 | F41: 0.1881 | G41: 0.1771 | H41: E1 | I41: 0.6987 | J41: 0.5296 | K41: E2 | L41: 0.109 | M41: 0.1001 | N41: E3 | O41: 0.8221 | P41: 0.6369 | Q41: E4 | R41: 0.1864 | S41: 0.1711 | T41: E5 | U41: 0.6968 | V41: 0.5297 | W41: E6 | X41: 0.1863 | Y41: 0.1713 | Z41: E7 | AA41: 0.6965 | AB41: 0.5258 | AC41: 0
B42: 87 | C42: -> | D42: 0 | E42: E0 | F42: 0.1887 | G42: 0.175 | H42: E1 | I42: 0.6949 | J42: 0.5296 | K42: E2 | L42: 0.1101 | M42: 0.1019 | N42: E3 | O42: 0.8207 | P42: 0.6364 | Q42: E4 | R42: 0.1872 | S42: 0.1729 | T42: E5 | U42: 0.6941 | V42: 0.5299 | W42: E6 | X42: 0.1859 | Y42: 0.1633 | Z42: E7 | AA42: 0.6982 | AB42: 0.5283 | AC42: 0.8905
A43: Média | F43: =AVERAGE(F38:F42) -> 0.18742 | G43: =AVERAGE(G38:G42) -> 0.17466 | I43: =AVERAGE(I38:I42) -> 0.69744 | J43: =AVERAGE(J38:J42) -> 0.53056 | L43: =AVERAGE(L38:L42) -> 0.10992 | M43: =AVERAGE(M38:M42) -> 0.10024 | O43: =AVERAGE(O38:O42) -> 0.82088 | P43: =AVERAGE(P38:P42) -> 0.63492 | R43: =AVERAGE(R38:R42) -> 0.18676 | S43: =AVERAGE(S38:S42) -> 0.17174 | U43: =AVERAGE(U38:U42) -> 0.69546 | V43: =AVERAGE(V38:V42) -> 0.52904 | X43: =AVERAGE(X38:X42) -> 0.18636 | Y43: =AVERAGE(Y38:Y42) -> 0.16796 | AA43: =AVERAGE(AA38:AA42) -> 0.6969 | AB43: =AVERAGE(AB38:AB42) -> 0.52502
...

Sheet Config Multisim

Sheet Acurácia
AK14: E3 E5 E7 | AL14: DP

Sheet Acurácia e DP
A1: CORRENTE
B2: 1 | C2: -> | D2: 0 | E2: E91 | F2: 1.5264 | G2: 1.0866 | H2: E92 | I2: 0 | J2: 0 | K2: 0 | L2: 0 | M2: 0 | N2: 0 | O2: 0 | P2: 0 | Q2: 0 | R2: 0 | S2: 0 | T2: 0 | U2: 0 | V2: 0 | W2: 0 | X2: 0 | Y2: 0 | Z2: 0 | AA2: 0 | AB2: 0
B3: 21 | C3: -> | D3: 0 | E3: E91 | F3: 1.5277 | G3: 1.0574 | H3: E92 | I3: 0 | J3: 0 | K3: 0 | L3: 0 | M3: 0 | N3: 0 | O3: 0 | P3: 0 | Q3: 0 | R3: 0 | S3: 0 | T3: 0 | U3: 0 | V3: 0 | W3: 0 | X3: 0 | Y3: 0 | Z3: 0 | AA3: 0 | AB3: 0
B4: 41 | C4: -> | D4: 0 | E4: E91 | F4: 1.5607 | G4: 1.0449 | H4: E92 | I4: 0 | J4: 0 | K4: 0 | L4: 0 | M4: 0 | N4: 0 | O4: 0 | P4: 0 | Q4: 0 | R4: 0 | S4: 0 | T4: 0 | U4: 0 | V4: 0 | W4: 0 | X4: 0 | Y4: 0 | Z4: 0 | AA4: 0 | AB4: 0
B5: 61 | C5: -> | D5: 0 | E5: E91 | F5: 1.5638 | G5: 1.038 | H5: E92 | I5: 0 | J5: 0 | K5: 0 | L5: 0 | M5: 0 | N5: 0 | O5: 0 | P5: 0 | Q5: 0 | R5: 0 | S5: 0 | T5: 0 | U5: 0 | V5: 0 | W5: 0 | X5: 0 | Y5: 0 | Z5: 0 | AA5: 0 | AB5: 0
B6: 81 | C6: -> | D6: 0 | E6: E91 | F6: 1.5324 | G6: 1.0791 | H6: E92 | I6: 0 | J6: 0 | K6: 0 | L6: 0 | M6: 0 | N6: 0 | O6: 0 | P6: 0 | Q6: 0 | R6: 0 | S6: 0 | T6: 0 | U6: 0 | V6: 0 | W6: 0 | X6: 0 | Y6: 0 | Z6: 0 | AA6: 0 | AB6: 0
A7: Média | F7: 1.5422 | G7: 1.0612
A8: STD | F8: 0.016521138 | G8: 0.018888833
A9: SNR (dB) | F9: 39.402015 | G9: 34.991842
A10: Valor simulado | F10: 1.056 | G10: 1.0518
A11: Acurácia | F11: 0.53958333 | G11: 0.99106294
A13: E1 conectado ao I1 e E0 conectado ao terra
B14: 3 | C14: -> | D14: 0 | E14: E0 | F14: 0.1079 | G14: 0.0984 | H14: E1 | I14: 1.0379 | J14: 0.8064 | K14: E2 | L14: 0.2812 | M14: 0.247 | N14: E3 | O14: 0.7971 | P14: 0.5988 | Q14: E4 | R14: 0.2839 | S14: 0.2535 | T14: E5 | U14: 0.7933 | V14: 0.5959 | W14: E6 | X14: 0.2837 | Y14: 0.2438 | Z14: E7 | AA14: 0.7922 | AB14: 0.5954
B15: 23 | C15: -> | D15: 0 | E15: E0 | F15: 0.1072 | G15: 0.0936 | H15: E1 | I15: 1.0344 | J15: 0.7984 | K15: E2 | L15: 0.2805 | M15: 0.2466 | N15: E3 | O15: 0.7957 | P15: 0.599 | Q15: E4 | R15: 0.2834 | S15: 0.2494 | T15: E5 | U15: 0.7926 | V15: 0.5971 | W15: E6 | X15: 0.2828 | Y15: 0.2497 | Z15: E7 | AA15: 0.7933 | AB15: 0.595
B16: 43 | C16: -> | D16: 0 | E16: E0 | F16: 0.108 | G16: 0.1032 | H16: E1 | I16: 1.0354 | J16: 0.7988 | K16: E2 | L16: 0.2784 | M16: 0.2488 | N16: E3 | O16: 0.7921 | P16: 0.5963 | Q16: E4 | R16: 0.283 | S16: 0.252 | T16: E5 | U16: 0.793 | V16: 0.6004 | W16: E6 | X16: 0.2832 | Y16: 0.2457 | Z16: E7 | AA16: 0.7928 | AB16: 0.5958
B17: 63 | C17: -> | D17: 0 | E17: E0 | F17: 0.1078 | G17: 0.0984 | H17: E1 | I17: 1.0389 | J17: 0.8091 | K17: E2 | L17: 0.2855 | M17: 0.2491 | N17: E3 | O17: 0.7939 | P17: 0.5977 | Q17: E4 | R17: 0.2862 | S17: 0.25 | T17: E5 | U17: 0.7932 | V17: 0.5948 | W17: E6 | X17: 0.2791 | Y17: 0.2451 | Z17: E7 | AA17: 0.7933 | AB17: 0.5959
B18: 83 | C18: -> | D18: 0 | E18: E0 | F18: 0.1099 | G18: 0.0965 | H18: E1 | I18: 1.0352 | J18: 0.8 | K18: E2 | L18: 0.2823 | M18: 0.2504 | N18: E3 | O18: 0.7939 | P18: 0.5952 | Q18: E4 | R18: 0.2839 | S18: 0.2515 | T18: E5 | U18: 0.7932 | V18: 0.5976 | W18: E6 | X18: 0.2823 | Y18: 0.2499 | Z18: E7 | AA18: 0.7946 | AB18: 0.5968
A19: Média | F19: 0.10816 | G19: 0.09802 | I19: 1.03636 | J19: 0.80254 | L19: 0.28158 | M19: 0.24838 | O19: 0.79454 | P19: 0.5974 | R19: 0.28408 | S19: 0.25128 | U19: 0.79306 | V19: 0.59716 | X19: 0.28222 | Y19: 0.24684 | AA19: 0.79324 | AB19: 0.59578
A20: STD | F20: 0.00091345498 | G20: 0.0031294728 | I20: 0.0017281204 | J20: 0.0043706292 | L20: 0.0023370066 | M20: 0.0014034244 | O20: 0.001713009 | P20: 0.001460137 | R20: 0.0011124747 | S20: 0.0014606848 | U20: 0.00024979992 | V20: 0.0018895502 | X20: 0.00162653 | Y20: 0.0024944739 | AA20: 0.00079145436 | AB20: 0.00060133186
A21: SNR (dB) | F21: 41.467591 | G21: 29.91687 | I21: 55.558733 | J21: 45.278454 | L21: 41.618837 | M21: 44.958552 | O21: 53.327122 | P21: 52.237432 | R21: 48.14301 | S21: 44.712028 | U21: 70.034275 | V21: 49.994645 | X21: 44.786514 | Y21: 39.908731 | AA21: 60.019575 | AB21: 59.919434
A22: Valor simulado | F22: 0.132 | G22: 0.1315 | I22: 1.0964 | J22: 0.9857 | L22: 0.3057 | M22: 0.3045 | O22: 0.8293 | P22: 0.7294 | R22: 0.3057 | S22: 0.3045 | U22: 0.8293 | V22: 0.7294 | X22: 0.3057 | Y22: 0.3045 | AA22: 0.8293 | AB22: 0.7294
A23: Acurácia | F23: 0.7795858 | G23: 0.65843705 | I23: 0.94206646 | J23: 0.77177462 | L23: 0.91434051 | M23: 0.77405588 | O23: 0.95625142 | P23: 0.77904252 | R23: 0.92389468 | S23: 0.78820439 | U23: 0.95430358 | V23: 0.77855181 | X23: 0.91680249 | Y23: 0.76640739 | AA23: 0.95454087 | AB23: 0.77572258
A25: E2 conectado ao I1 e E1 conectado ao terra
B26: 5 | C26: -> | D26: 0 | E26: E0 | F26: 0.879 | G26: 0.6562 | H26: E1 | I26: 0.1083 | J26: 0.0949 | K26: E2 | L26: 0.9499 | M26: 0.7213 | N26: E3 | O26: 0.3684 | P26: 0.3206 | Q26: E4 | R26: 0.8845 | S26: 0.6592 | T26: E5 | U26: 0.3699 | V26: 0.3274 | W26: E6 | X26: 0.8736 | Y26: 0.6356 | Z26: E7 | AA26: 0.372 | AB26: 0.3263
B27: 25 | C27: -> | D27: 0 | E27: E0 | F27: 0.8731 | G27: 0.6404 | H27: E1 | I27: 0.1058 | J27: 0.0944 | K27: E2 | L27: 0.945 | M27: 0.6995 | N27: E3 | O27: 0.3733 | P27: 0.3192 | Q27: E4 | R27: 0.8728 | S27: 0.6538 | T27: E5 | U27: 0.3686 | V27: 0.3257 | W27: E6 | X27: 0.875 | Y27: 0.6702 | Z27: E7 | AA27: 0.3627 | AB27: 0.342
B28: 45 | C28: -> | D28: 0 | E28: E0 | F28: 0.8767 | G28: 0.6467 | H28: E1 | I28: 0.1074 | J28: 0.0949 | K28: E2 | L28: 0.9518 | M28: 0.7227 | N28: E3 | O28: 0.3706 | P28: 0.3211 | Q28: E4 | R28: 0.8792 | S28: 0.6575 | T28: E5 | U28: 0.3681 | V28: 0.319 | W28: E6 | X28: 0.8755 | Y28: 0.6535 | Z28: E7 | AA28: 0.3684 | AB28: 0.3297
B29: 65 | C29: -> | D29: 0 | E29: E0 | F29: 0.8772 | G29: 0.6589 | H29: E1 | I29: 0.1073 | J29: 0.0946 | K29: E2 | L29: 0.9529 | M29: 0.72 | N29: E3 | O29: 0.3697 | P29: 0.3203 | Q29: E4 | R29: 0.8809 | S29: 0.6576 | T29: E5 | U29: 0.3668 | V29: 0.3206 | W29: E6 | X29: 0.8776 | Y29: 0.6578 | Z29: E7 | AA29: 0.3699 | AB29: 0.335
B30: 85 | C30: -> | D30: 0 | E30: E0 | F30: 0.8793 | G30: 0.6552 | H30: E1 | I30: 0.1082 | J30: 0.0946 | K30: E2 | L30: 0.9527 | M30: 0.7244 | N30: E3 | O30: 0.3695 | P30: 0.3248 | Q30: E4 | R30: 0.8818 | S30: 0.6558 | T30: E5 | U30: 0.3691 | V30: 0.3201 | W30: E6 | X30: 0.8755 | Y30: 0.653 | Z30: E7 | AA30: 0.367 | AB30: 0.3302
A31: Média | F31: 0.87706 | G31: 0.65148 | I31: 0.1074 | J31: 0.09468 | L31: 0.95046 | M31: 0.71758 | O31: 0.3703 | P31: 0.3212 | R31: 0.87984 | S31: 0.65678 | U31: 0.3685 | V31: 0.32256 | X31: 0.87544 | Y31: 0.65402 | AA31: 0.368 | AB31: 0.33264
A32: STD | F32: 0.0022186482 | G32: 0.0068816858 | I32: 0.00089666047 | J32: 0.00019390719 | L32: 0.0029288906 | M32: 0.0091575979 | O32: 0.0016552945 | P32: 0.001904731 | R32: 0.0039154055 | S32: 0.0018378248 | U32: 0.0010373042 | V32: 0.0033422148 | X32: 0.0012846789 | Y32: 0.011105746 | AA32: 0.0031260198 | AB32: 0.0054400735
A33: SNR (dB) | F33: 51.938817 | G33: 39.524125 | I33: 41.567525 | J33: 53.773287 | L33: 50.224614 | M33: 37.881775 | O33: 46.993569 | P33: 44.538838 | R33: 47.032539 | S33: 51.062316 | U33: 51.010627 | V33: 39.691523 | X33: 56.668636 | Y33: 35.400866 | AA33: 41.417122 | AB33: 35.727394
A34: Valor simulado | F34: 0.9229 | G34: 0.8184 | I34: 0.132 | J34: 0.1315 | L34: 0.9984 | M34: 0.8908 | O34: 0.3992 | P34: 0.3976 | R34: 0.9229 | S34: 0.8184 | U34: 0.3992 | V34: 0.3976 | X34: 0.9229 | Y34: 0.8184 | AA34: 0.3992 | AB34: 0.3976
A35: Acurácia | F35: 0.94773448 | G35: 0.74378339 | I35: 0.77094972 | J35: 0.61111111 | L35: 0.94956127 | M35: 0.75860531 | O35: 0.92195517 | P35: 0.76214197 | R35: 0.95105928 | S35: 0.75392064 | U35: 0.91668928 | V35: 0.76736111 | X35: 0.94578726 | Y35: 0.74866212 | AA35: 0.91521739 | AB35: 0.8047138
A37: E3 conectado ao I1 e E2 conectado ao terra
B38: 7 | C38: -> | D38: 0 | E38: E0 | F38: 0.182 | G38: 0.1653 | H38: E1 | I38: 0.6994 | J38: 0.5305 | K38: E2 | L38: 0.1101 | M38: 0.0982 | N38: E3 | O38: 0.8185 | P38: 0.6357 | Q38: E4 | R38: 0.1858 | S38: 0.1727 | T38: E5 | U38: 0.6951 | V38: 0.527 | W38: E6 | X38: 0.1874 | Y38: 0.1629 | Z38: E7 | AA38: 0.6959 | AB38: 0.5208
B39: 27 | C39: -> | D39: 0 | E39: E0 | F39: 0.1877 | G39: 0.1776 | H39: E1 | I39: 0.697 | J39: 0.5303 | K39: E2 | L39: 0.1108 | M39: 0.1005 | N39: E3 | O39: 0.8224 | P39: 0.6234 | Q39: E4 | R39: 0.1873 | S39: 0.1704 | T39: E5 | U39: 0.6958 | V39: 0.5279 | W39: E6 | X39: 0.1859 | Y39: 0.1721 | Z39: E7 | AA39: 0.697 | AB39: 0.5267
B40: 47 | C40: -> | D40: 0 | E40: E0 | F40: 0.1906 | G40: 0.1783 | H40: E1 | I40: 0.6972 | J40: 0.5328 | K40: E2 | L40: 0.1096 | M40: 0.1005 | N40: E3 | O40: 0.8207 | P40: 0.6422 | Q40: E4 | R40: 0.1871 | S40: 0.1716 | T40: E5 | U40: 0.6955 | V40: 0.5307 | W40: E6 | X40: 0.1863 | Y40: 0.1702 | Z40: E7 | AA40: 0.6969 | AB40: 0.5235
B41: 67 | C41: -> | D41: 0 | E41: E0 | F41: 0.1881 | G41: 0.1771 | H41: E1 | I41: 0.6987 | J41: 0.5296 | K41: E2 | L41: 0.109 | M41: 0.1001 | N41: E3 | O41: 0.8221 | P41: 0.6369 | Q41: E4 | R41: 0.1864 | S41: 0.1711 | T41: E5 | U41: 0.6968 | V41: 0.5297 | W41: E6 | X41: 0.1863 | Y41: 0.1713 | Z41: E7 | AA41: 0.6965 | AB41: 0.5258
B42: 87 | C42: -> | D42: 0 | E42: E0 | F42: 0.1887 | G42: 0.175 | H42: E1 | I42: 0.6949 | J42: 0.5296 | K42: E2 | L42: 0.1101 | M42: 0.1019 | N42: E3 | O42: 0.8207 | P42: 0.6364 | Q42: E4 | R42: 0.1872 | S42: 0.1729 | T42: E5 | U42: 0.6941 | V42: 0.5299 | W42: E6 | X42: 0.1859 | Y42: 0.1633 | Z42: E7 | AA42: 0.6982 | AB42: 0.5283
A43: Média | F43: 0.18742 | G43: 0.17466 | I43: 0.69744 | J43: 0.53056 | L43: 0.10992 | M43: 0.10024 | O43: 0.82088 | P43: 0.63492 | R43: 0.18676 | S43: 0.17174 | U43: 0.69546 | V43: 0.52904 | X43: 0.18636 | Y43: 0.16796 | AA43: 0.6969 | AB43: 0.52502
...

Sheet DP2
AF2: Eletrodos de medição
A3: 1 | B3: -> | D3: E91 | E3: 1.5264 | F3: 1.0866 | G3: E92 | H3: 0 | I3: 0 | AF3: Eletrodos pares | AH3: Eletrodos ímpares
A4: =A3+1 -> 2 | B4: -> | C4: E1 | D4: I1 | E4: e | F4: E0 | G4: Terra | AF4: FREQ1 | AG4: FREQ2 | AH4: FREQ1 | AI4: FREQ2
A5: =A4+1 -> 3 | B5: -> | J5: E2 | K5: 0.2812 | L5: 0.247 | M5: E3 | N5: 0.7971 | O5: 0.5988 | P5: E4 | Q5: 0.2839 | R5: 0.2535 | S5: E5 | T5: 0.7933 | U5: 0.5959 | V5: E6 | W5: 0.2837 | X5: 0.2438 | Y5: E7 | Z5: 0.7922 | AA5: 0.5954 | AD5: Eletrodos de injeção | AE5: E1 | AF5: =_xlfn.STDEV.P(E5,K5,Q5,W5) -> 0.0012283684 | AG5: =_xlfn.STDEV.P(F5,L5,R5,X5) -> 0.0040356743 | AH5: =_xlfn.STDEV.P(H5,N5,T5,Z5) -> 0.0020992062 | AI5: =_xlfn.STDEV.P(I5,O5,U5,AA5) -> 0.0014988885
A6: =A5+1 -> 4 | B6: -> | C6: E2 | D6: I1 | E6: e | F6: E1 | G6: Terra
A7: =A6+1 -> 5 | B7: -> | D7: E0 | E7: 0.879 | F7: 0.6562 | M7: E3 | N7: 0.3684 | O7: 0.3206 | P7: E4 | Q7: 0.8845 | R7: 0.6592 | S7: E5 | T7: 0.3699 | U7: 0.3274 | V7: E6 | W7: 0.8736 | X7: 0.6356 | Y7: E7 | Z7: 0.372 | AA7: 0.3263 | AE7: E2 | AF7: =_xlfn.STDEV.P(E7,K7,Q7,W7) -> 0.0044499688 | AG7: =_xlfn.STDEV.P(F7,L7,R7,X7) -> 0.010489783 | AH7: =_xlfn.STDEV.P(H7,N7,T7,Z7) -> 0.0014764823 | AI7: =_xlfn.STDEV.P(I7,O7,U7,AA7) -> 0.0029803057
A8: =A7+1 -> 6 | B8: -> | C8: E3 | D8: I1 | E8: e | F8: E2 | G8: Terra
A9: =A8+1 -> 7 | B9: -> | D9: E0 | E9: 0.182 | F9: 0.1653 | G9: E1 | H9: 0.6994 | I9: 0.5305 | P9: E4 | Q9: 0.1858 | R9: 0.1727 | S9: E5 | T9: 0.6951 | U9: 0.527 | V9: E6 | W9: 0.1874 | X9: 0.1629 | Y9: E7 | Z9: 0.6959 | AA9: 0.5208 | AE9: E3 | AF9: =_xlfn.STDEV.P(E9,K9,Q9,W9) -> 0.002264705 | AG9: =_xlfn.STDEV.P(F9,L9,R9,X9) -> 0.004170798 | AH9: =_xlfn.STDEV.P(H9,N9,T9,Z9) -> 0.0018672618 | AI9: =_xlfn.STDEV.P(I9,O9,U9,AA9) -> 0.0040108187
A10: =A9+1 -> 8 | B10: -> | C10: E4 | D10: I1 | E10: e | F10: E3 | G10: Terra
A11: =A10+1 -> 9 | B11: -> | D11: E0 | E11: 0.753 | F11: 0.5763 | G11: E1 | H11: 0.2337 | I11: 0.2024 | J11: E2 | K11: 0.7412 | L11: 0.5508 | S11: E5 | T11: 0.2332 | U11: 0.2061 | V11: E6 | W11: 0.7421 | X11: 0.5516 | Y11: E7 | Z11: 0.2316 | AA11: 0.2185 | AE11: E4 | AF11: =_xlfn.STDEV.P(E11,K11,Q11,W11) -> 0.0053630423 | AG11: =_xlfn.STDEV.P(F11,L11,R11,X11) -> 0.01183676 | AH11: =_xlfn.STDEV.P(H11,N11,T11,Z11) -> 0.00089566859 | AI11: =_xlfn.STDEV.P(I11,O11,U11,AA11) -> 0.0068852499
A12: =A11+1 -> 10 | B12: -> | C12: E5 | D12: I1 | E12: e | F12: E4 | G12: Terra
A13: =A12+1 -> 11 | B13: -> | D13: E0 | E13: 0.2442 | F13: 0.2204 | G13: E1 | H13: 0.7491 | I13: 0.5768 | J13: E2 | K13: 0.2436 | L13: 0.2139 | M13: E3 | N13: 0.7589 | O13: 0.5701 | V13: E6 | W13: 0.2451 | X13: 0.2202 | Y13: E7 | Z13: 0.7565 | AA13: 0.5669 | AE13: E5 | AF13: =_xlfn.STDEV.P(E13,K13,Q13,W13) -> 0.0006164414 | AG13: =_xlfn.STDEV.P(F13,L13,R13,X13) -> 0.0030180936 | AH13: =_xlfn.STDEV.P(H13,N13,T13,Z13) -> 0.004170798 | AI13: =_xlfn.STDEV.P(I13,O13,U13,AA13) -> 0.0041249916
A14: =A13+1 -> 12 | B14: -> | C14: E6 | D14: I1 | E14: e | F14: E5 | G14: Terra
A15: =A14+1 -> 13 | B15: -> | D15: E0 | E15: 0.8567 | F15: 0.6436 | G15: E1 | H15: 0.345 | I15: 0.3043 | J15: E2 | K15: 0.8549 | L15: 0.6414 | M15: E3 | N15: 0.3462 | O15: 0.3036 | P15: E4 | Q15: 0.8564 | R15: 0.6433 | Y15: E7 | Z15: 0.3458 | AA15: 0.3122 | AE15: E6 | AF15: =_xlfn.STDEV.P(E15,K15,Q15,W15) -> 0.00078740079 | AG15: =_xlfn.STDEV.P(F15,L15,R15,X15) -> 0.00097410928 | AH15: =_xlfn.STDEV.P(H15,N15,T15,Z15) -> 0.00049888765 | AI15: =_xlfn.STDEV.P(I15,O15,U15,AA15) -> 0.0038995726
A16: =A15+1 -> 14 | B16: -> | C16: E7 | D16: I1 | E16: e | F16: E6 | G16: Terra
A17: =A16+1 -> 15 | B17: -> | D17: E0 | E17: 0.1713 | F17: 0.1623 | G17: E1 | H17: 0.682 | I17: 0.5044 | J17: E2 | K17: 0.1679 | L17: 0.1498 | M17: E3 | N17: 0.6823 | O17: 0.5064 | P17: E4 | Q17: 0.1697 | R17: 0.1526 | S17: E5 | T17: 0.6797 | U17: 0.5016 | AE17: E7 | AF17: =_xlfn.STDEV.P(E17,K17,Q17,W17) -> 0.0013888444 | AG17: =_xlfn.STDEV.P(F17,L17,R17,X17) -> 0.0053559935 | AH17: =_xlfn.STDEV.P(H17,N17,T17,Z17) -> 0.0011614168 | AI17: =_xlfn.STDEV.P(I17,O17,U17,AA17) -> 0.0019686431
A18: =A17+1 -> 16 | B18: -> | C18: E0 | D18: I1 | E18: e | F18: E7 | G18: Terra
A19: =A18+1 -> 17 | B19: -> | G19: E1 | H19: 0.4504 | I19: 0.3746 | J19: E2 | K19: 0.9419 | L19: 0.6982 | M19: E3 | N19: 0.4518 | O19: 0.393 | P19: E4 | Q19: 0.9466 | R19: 0.7178 | S19: E5 | T19: 0.4487 | U19: 0.3874 | V19: E6 | W19: 0.9511 | X19: 0.7056 | AE19: E8 | AF19: =_xlfn.STDEV.P(E19,K19,Q19,W19) -> 0.0037561801 | AG19: =_xlfn.STDEV.P(F19,L19,R19,X19) -> 0.008081254 | AH19: =_xlfn.STDEV.P(H19,N19,T19,Z19) -> 0.0012675436 | AI19: =_xlfn.STDEV.P(I19,O19,U19,AA19) -> 0.0077010822
AD30: 0.0019
AD31: 0.0036
AC33: =(AD31-AD30)/AD30 -> 0.89473684
