Workbook

Sheet Dado Bruto
A1: 1
A2: =A1+1 -> 2 | B2: -> | C2: E1 | D2: I1 | E2: e | F2: E0 | G2: Terra
A3: =A2+1 -> 3 | B3: -> | C3: E91 | D3: 1.5044 | E3: 1.0908 | F3: E92 | G3: 0 | H3: 0 | I3: E0 | J3: 0.1098 | K3: 0.0985 | L3: E1 | M3: 1.0209 | N3: 0.9028 | O3: E2 | P3: 0.2806 | Q3: 0.251 | R3: E3 | S3: 0.7968 | T3: 0.7066 | U3: E4 | V3: 0.2827 | W3: 0.2519 | X3: E5 | Y3: 0.7964 | Z3: 0.7018 | AA3: E6 | AB3: 0.2739 | AC3: 0.2426 | AD3: E7 | AE3: 0.797 | AF3: 0.6766
A4: =A3+1 -> 4 | B4: -> | C4: E2 | D4: I1 | E4: e | F4: E1 | G4: Terra
A5: =A4+1 -> 5 | B5: -> | C5: E91 | D5: 1.482 | E5: 1.1035 | F5: E92 | G5: 0 | H5: 0 | I5: E0 | J5: 0.8906 | K5: 0.806 | L5: E1 | M5: 0.1091 | N5: 0.1008 | O5: E2 | P5: 0.9461 | Q5: 0.8653 | R5: E3 | S5: 0.3736 | T5: 0.3443 | U5: E4 | V5: 0.887 | W5: 0.8132 | X5: E5 | Y5: 0.3735 | Z5: 0.3431 | AA5: E6 | AB5: 0.8831 | AC5: 0.8104 | AD5: E7 | AE5: 0.3735 | AF5: 0.348
A6: =A5+1 -> 6 | B6: -> | C6: E3 | D6: I1 | E6: e | F6: E2 | G6: Terra
A7: =A6+1 -> 7 | B7: -> | C7: E91 | D7: 1.4674 | E7: 1.0915 | F7: E92 | G7: 0 | H7: 0 | I7: E0 | J7: 0.1908 | K7: 0.1782 | L7: E1 | M7: 0.7047 | N7: 0.6418 | O7: E2 | P7: 0.1128 | Q7: 0.1044 | R7: E3 | S7: 0.8381 | T7: 0.7652 | U7: E4 | V7: 0.1902 | W7: 0.1757 | X7: E5 | Y7: 0.7036 | Z7: 0.6396 | AA7: E6 | AB7: 0.1892 | AC7: 0.1748 | AD7: E7 | AE7: 0.7044 | AF7: 0.6375
A8: =A7+1 -> 8 | B8: -> | C8: E4 | D8: I1 | E8: e | F8: E3 | G8: Terra
A9: =A8+1 -> 9 | B9: -> | C9: E91 | D9: 1.507 | E9: 1.0882 | F9: E92 | G9: 0 | H9: 0 | I9: E0 | J9: 0.7556 | K9: 0.7014 | L9: E1 | M9: 0.2419 | N9: 0.2245 | O9: E2 | P9: 0.7584 | Q9: 0.6993 | R9: E3 | S9: 0.1102 | T9: 0.1028 | U9: E4 | V9: 0.8943 | W9: 0.83 | X9: E5 | Y9: 0.2435 | Z9: 0.228 | AA9: E6 | AB9: 0.7582 | AC9: 0.6972 | AD9: E7 | AE9: 0.2441 | AF9: 0.2259
A10: =A9+1 -> 10 | B10: -> | C10: E5 | D10: I1 | E10: e | F10: E4 | G10: Terra
A11: =A10+1 -> 11 | B11: -> | C11: E91 | D11: 1.5108 | E11: 1.0771 | F11: E92 | G11: 0 | H11: 0 | I11: E0 | J11: 0.2468 | K11: 0.2277 | L11: E1 | M11: 0.7605 | N11: 0.6842 | O11: E2 | P11: 0.2452 | Q11: 0.2237 | R11: E3 | S11: 0.7617 | T11: 0.6863 | U11: E4 | V11: 0.1059 | W11: 0.0963 | X11: E5 | Y11: 0.9782 | Z11: 0.8845 | AA11: E6 | AB11: 0.2461 | AC11: 0.2244 | AD11: E7 | AE11: 0.761 | AF11: 0.6819
A12: =A11+1 -> 12 | B12: -> | C12: E6 | D12: I1 | E12: e | F12: E5 | G12: Terra
A13: =A12+1 -> 13 | B13: -> | C13: E91 | D13: 1.5157 | E13: 1.0797 | F13: E92 | G13: 0 | H13: 0 | I13: E0 | J13: 0.8622 | K13: 0.7944 | L13: E1 | M13: 0.3508 | N13: 0.3253 | O13: E2 | P13: 0.8609 | Q13: 0.7917 | R13: E3 | S13: 0.3468 | T13: 0.3211 | U13: E4 | V13: 0.8623 | W13: 0.7953 | X13: E5 | Y13: 0.1065 | Z13: 0.0989 | AA13: E6 | AB13: 0.9092 | AC13: 0.8381 | AD13: E7 | AE13: 0.3475 | AF13: 0.326
A14: =A13+1 -> 14 | B14: -> | C14: E7 | D14: I1 | E14: e | F14: E6 | G14: Terra
A15: =A14+1 -> 15 | B15: -> | C15: E91 | D15: 1.4926 | E15: 1.0851 | F15: E92 | G15: 0 | H15: 0 | I15: E0 | J15: 0.1583 | K15: 0.1514 | L15: E1 | M15: 0.6709 | N15: 0.5905 | O15: E2 | P15: 0.1585 | Q15: 0.1428 | R15: E3 | S15: 0.6729 | T15: 0.593 | U15: E4 | V15: 0.1601 | W15: 0.1424 | X15: E5 | Y15: 0.6723 | Z15: 0.5952 | AA15: E6 | AB15: 0.1076 | AC15: 0.0968 | AD15: E7 | AE15: 0.997 | AF15: 0.8806
A16: =A15+1 -> 16 | B16: -> | C16: E0 | D16: I1 | E16: e | F16: E7 | G16: Terra
A17: =A16+1 -> 17 | B17: -> | C17: E91 | D17: 1.4985 | E17: 1.0746 | F17: E92 | G17: 0 | H17: 0 | I17: E0 | J17: 1.062 | K17: 0.94 | L17: E1 | M17: 0.4571 | N17: 0.4067 | O17: E2 | P17: 0.9538 | Q17: 0.8445 | R17: E3 | S17: 0.4574 | T17: 0.4066 | U17: E4 | V17: 0.9627 | W17: 0.8533 | X17: E5 | Y17: 0.4573 | Z17: 0.4057 | AA17: E6 | AB17: 0.9602 | AC17: 0.8512 | AD17: E7 | AE17: 0.1057 | AF17: 0.095
A18: =A17+1 -> 18
A19: =A18+1 -> 19
A20: =A19+1 -> 20
A21: =A20+1 -> 21 | B21: ->
A22: =A21+1 -> 22 | B22: -> | C22: E1 | D22: I1 | E22: e | F22: E0 | G22: Terra
A23: =A22+1 -> 23 | B23: -> | C23: E91 | D23: 1.4996 | E23: 1.0863 | F23: E92 | G23: 0 | H23: 0 | I23: E0 | J23: 0.1092 | K23: 0.0984 | L23: E1 | M23: 1.0108 | N23: 0.8892 | O23: E2 | P23: 0.2792 | Q23: 0.2526 | R23: E3 | S23: 0.7936 | T23: 0.7096 | U23: E4 | V23: 0.2789 | W23: 0.2521 | X23: E5 | Y23: 0.7928 | Z23: 0.7011 | AA23: E6 | AB23: 0.2805 | AC23: 0.2458 | AD23: E7 | AE23: 0.7944 | AF23: 0.692
A24: =A23+1 -> 24 | B24: -> | C24: E2 | D24: I1 | E24: e | F24: E1 | G24: Terra
A25: =A24+1 -> 25 | B25: -> | C25: E91 | D25: 1.472 | E25: 1.1256 | F25: E92 | G25: 0 | H25: 0 | I25: E0 | J25: 0.8879 | K25: 0.8138 | L25: E1 | M25: 0.1091 | N25: 0.0998 | O25: E2 | P25: 0.9482 | Q25: 0.8688 | R25: E3 | S25: 0.3741 | T25: 0.3452 | U25: E4 | V25: 0.8885 | W25: 0.8156 | X25: E5 | Y25: 0.3742 | Z25: 0.3443 | AA25: E6 | AB25: 0.8872 | AC25: 0.8135 | AD25: E7 | AE25: 0.3746 | AF25: 0.3454
A26: =A25+1 -> 26 | B26: -> | C26: E3 | D26: I1 | E26: e | F26: E2 | G26: Terra
A27: =A26+1 -> 27 | B27: -> | C27: E91 | D27: 1.5179 | E27: 1.0718 | F27: E92 | G27: 0 | H27: 0 | I27: E0 | J27: 0.2195 | K27: 0.2067 | L27: E1 | M27: 0.7039 | N27: 0.6414 | O27: E2 | P27: 0.1135 | Q27: 0.1042 | R27: E3 | S27: 0.8378 | T27: 0.7639 | U27: E4 | V27: 0.19 | W27: 0.1748 | X27: E5 | Y27: 0.7038 | Z27: 0.637 | AA27: E6 | AB27: 0.1908 | AC27: 0.1725 | AD27: E7 | AE27: 0.6957 | AF27: 0.6159
A28: =A27+1 -> 28 | B28: -> | C28: E4 | D28: I1 | E28: e | F28: E3 | G28: Terra
A29: =A28+1 -> 29 | B29: -> | C29: E91 | D29: 1.4634 | E29: 1.0962 | F29: E92 | G29: 0 | H29: 0 | I29: E0 | J29: 0.7555 | K29: 0.7018 | L29: E1 | M29: 0.2413 | N29: 0.2266 | O29: E2 | P29: 0.7563 | Q29: 0.6996 | R29: E3 | S29: 0.1097 | T29: 0.1027 | U29: E4 | V29: 0.8997 | W29: 0.8343 | X29: E5 | Y29: 0.2433 | Z29: 0.2276 | AA29: E6 | AB29: 0.7563 | AC29: 0.7012 | AD29: E7 | AE29: 0.2434 | AF29: 0.231
A30: =A29+1 -> 30 | B30: -> | C30: E5 | D30: I1 | E30: e | F30: E4 | G30: Terra
A31: =A30+1 -> 31 | B31: -> | C31: E91 | D31: 1.5126 | E31: 1.0782 | F31: E92 | G31: 0 | H31: 0 | I31: E0 | J31: 0.2469 | K31: 0.2279 | L31: E1 | M31: 0.7607 | N31: 0.6858 | O31: E2 | P31: 0.2452 | Q31: 0.2255 | R31: E3 | S31: 0.7611 | T31: 0.688 | U31: E4 | V31: 0.1065 | W31: 0.0972 | X31: E5 | Y31: 0.9801 | Z31: 0.8837 | AA31: E6 | AB31: 0.2456 | AC31: 0.2253 | AD31: E7 | AE31: 0.7606 | AF31: 0.6817
A32: =A31+1 -> 32 | B32: -> | C32: E6 | D32: I1 | E32: e | F32: E5 | G32: Terra
A33: =A32+1 -> 33 | B33: -> | C33: E91 | D33: 1.4774 | E33: 1.1154 | F33: E92 | G33: 0 | H33: 0 | I33: E0 | J33: 0.8626 | K33: 0.793 | L33: E1 | M33: 0.3384 | N33: 0.3141 | O33: E2 | P33: 0.8573 | Q33: 0.7892 | R33: E3 | S33: 0.3478 | T33: 0.3224 | U33: E4 | V33: 0.8624 | W33: 0.794 | X33: E5 | Y33: 0.1064 | Z33: 0.0985 | AA33: E6 | AB33: 0.9085 | AC33: 0.8346 | AD33: E7 | AE33: 0.3465 | AF33: 0.3198
A34: =A33+1 -> 34 | B34: -> | C34: E7 | D34: I1 | E34: e | F34: E6 | G34: Terra
A35: =A34+1 -> 35 | B35: -> | C35: E91 | D35: 1.4977 | E35: 1.0867 | F35: E92 | G35: 0 | H35: 0 | I35: E0 | J35: 0.1583 | K35: 0.1511 | L35: E1 | M35: 0.6727 | N35: 0.5964 | O35: E2 | P35: 0.1588 | Q35: 0.1429 | R35: E3 | S35: 0.6751 | T35: 0.5887 | U35: E4 | V35: 0.1601 | W35: 0.1422 | X35: E5 | Y35: 0.6729 | Z35: 0.5892 | AA35: E6 | AB35: 0.1076 | AC35: 0.0962 | AD35: E7 | AE35: 0.9999 | AF35: 0.8864
A36: =A35+1 -> 36 | B36: -> | C36: E0 | D36: I1 | E36: e | F36: E7 | G36: Terra
A37: =A36+1 -> 37 | B37: -> | C37: E91 | D37: 1.5215 | E37: 1.0703 | F37: E92 | G37: 0 | H37: 0 | I37: E0 | J37: 1.0626 | K37: 0.94 | L37: E1 | M37: 0.4564 | N37: 0.4057 | O37: E2 | P37: 0.9557 | Q37: 0.8468 | R37: E3 | S37: 0.4581 | T37: 0.4062 | U37: E4 | V37: 0.9641 | W37: 0.8554 | X37: E5 | Y37: 0.4568 | Z37: 0.4058 | AA37: E6 | AB37: 0.9542 | AC37: 0.845 | AD37: E7 | AE37: 0.1057 | AF37: 0.095
A38: =A37+1 -> 38
A39: =A38+1 -> 39
A40: =A39+1 -> 40 | B40: ->
...

Sheet Dados processados
A1: E1 conectado ao I1 e E0 conectado ao terra
B2: {=_xlfn._xlws.FILTER('Dado Bruto'!A:AF, ('Dado Bruto'!A:A=3) + ('Dado Bruto'!A:A=23) + ('Dado Bruto'!A:A=43)+ ('Dado Bruto'!A:A=63)+ ('Dado Bruto'!A:A=83), "Não encontrado")} -> 3 | C2: -> | D2: E91 | E2: 1.5044 | F2: 1.0908 | G2: E92 | H2: 0 | I2: 0 | J2: E0 | K2: 0.1098 | L2: 0.0985 | M2: E1 | N2: 1.0209 | O2: 0.9028 | P2: E2 | Q2: 0.2806 | R2: 0.251 | S2: E3 | T2: 0.7968 | U2: 0.7066 | V2: E4 | W2: 0.2827 | X2: 0.2519 | Y2: E5 | Z2: 0.7964 | AA2: 0.7018 | AB2: E6 | AC2: 0.2739 | AD2: 0.2426 | AE2: E7 | AF2: 0.797 | AG2: 0.6766
B3: 23 | C3: -> | D3: E91 | E3: 1.4996 | F3: 1.0863 | G3: E92 | H3: 0 | I3: 0 | J3: E0 | K3: 0.1092 | L3: 0.0984 | M3: E1 | N3: 1.0108 | O3: 0.8892 | P3: E2 | Q3: 0.2792 | R3: 0.2526 | S3: E3 | T3: 0.7936 | U3: 0.7096 | V3: E4 | W3: 0.2789 | X3: 0.2521 | Y3: E5 | Z3: 0.7928 | AA3: 0.7011 | AB3: E6 | AC3: 0.2805 | AD3: 0.2458 | AE3: E7 | AF3: 0.7944 | AG3: 0.692
B4: 43 | C4: -> | D4: E91 | E4: 1.5152 | F4: 1.0755 | G4: E92 | H4: 0 | I4: 0 | J4: E0 | K4: 0.1094 | L4: 0.0985 | M4: E1 | N4: 1.0229 | O4: 0.9034 | P4: E2 | Q4: 0.2841 | R4: 0.2508 | S4: E3 | T4: 0.793 | U4: 0.6932 | V4: E4 | W4: 0.2813 | X4: 0.2441 | Y4: E5 | Z4: 0.7888 | AA4: 0.6836 | AB4: E6 | AC4: 0.2801 | AD4: 0.2442 | AE4: E7 | AF4: 0.7905 | AG4: 0.6664
B5: 63 | C5: -> | D5: E91 | E5: 1.4655 | F5: 1.094 | G5: E92 | H5: 0 | I5: 0 | J5: E0 | K5: 0.1103 | L5: 0.0987 | M5: E1 | N5: 1.0214 | O5: 0.9071 | P5: E2 | Q5: 0.2814 | R5: 0.2509 | S5: E3 | T5: 0.7968 | U5: 0.7069 | V5: E4 | W5: 0.2816 | X5: 0.2524 | Y5: E5 | Z5: 0.7962 | AA5: 0.704 | AB5: E6 | AC5: 0.2805 | AD5: 0.251 | AE5: E7 | AF5: 0.7963 | AG5: 0.7037
B6: 83 | C6: -> | D6: E91 | E6: 1.485 | F6: 1.0909 | G6: E92 | H6: 0 | I6: 0 | J6: E0 | K6: 0.1095 | L6: 0.0973 | M6: E1 | N6: 1.0222 | O6: 0.9056 | P6: E2 | Q6: 0.2815 | R6: 0.2474 | S6: E3 | T6: 0.7964 | U6: 0.7064 | V6: E4 | W6: 0.2818 | X6: 0.2512 | Y6: E5 | Z6: 0.7954 | AA6: 0.7032 | AB6: E6 | AC6: 0.281 | AD6: 0.2508 | AE6: E7 | AF6: 0.7935 | AG6: 0.7016
A7: Média | E7: =AVERAGE(E2:E6) -> 1.49394 | F7: =AVERAGE(F2:F6) -> 1.0875 | K7: =AVERAGE(K2:K6) -> 0.10964 | L7: =AVERAGE(L2:L6) -> 0.09828 | N7: =AVERAGE(N2:N6) -> 1.01964 | O7: =AVERAGE(O2:O6) -> 0.90162 | Q7: =AVERAGE(Q2:Q6) -> 0.28136 | R7: =AVERAGE(R2:R6) -> 0.25054 | T7: =AVERAGE(T2:T6) -> 0.79532 | U7: =AVERAGE(U2:U6) -> 0.70454 | W7: =AVERAGE(W2:W6) -> 0.28126 | X7: =AVERAGE(X2:X6) -> 0.25034 | Z7: =AVERAGE(Z2:Z6) -> 0.79392 | AA7: =AVERAGE(AA2:AA6) -> 0.69874 | AC7: =AVERAGE(AC2:AC6) -> 0.2792 | AD7: =AVERAGE(AD2:AD6) -> 0.24688 | AF7: =AVERAGE(AF2:AF6) -> 0.79434 | AG7: =AVERAGE(AG2:AG6) -> 0.68806
A8: STD | E8: =_xlfn.STDEV.P(E2:E6) -> 0.017217387 | F8: =_xlfn.STDEV.P(F2:F6) -> 0.0064829006 | K8: =_xlfn.STDEV.P(K2:K6) -> 0.00038262253 | L8: =_xlfn.STDEV.P(L2:L6) -> 0.00049959984 | N8: =_xlfn.STDEV.P(N2:N6) -> 0.0044724043 | O8: =_xlfn.STDEV.P(O2:O6) -> 0.0063982498 | Q8: =_xlfn.STDEV.P(Q2:Q6) -> 0.001598249 | R8: =_xlfn.STDEV.P(R2:R6) -> 0.0017036432 | T8: =_xlfn.STDEV.P(T2:T6) -> 0.0016666133 | U8: =_xlfn.STDEV.P(U2:U6) -> 0.0057874347 | W8: =_xlfn.STDEV.P(W2:W6) -> 0.0012690154 | X8: =_xlfn.STDEV.P(X2:X6) -> 0.0031449006 | Z8: =_xlfn.STDEV.P(Z2:Z6) -> 0.0028638436 | AA8: =_xlfn.STDEV.P(AA2:AA6) -> 0.0076382197 | AC8: =_xlfn.STDEV.P(AC2:AC6) -> 0.002665333 | AD8: =_xlfn.STDEV.P(AD2:AD6) -> 0.0034353457 | AF8: =_xlfn.STDEV.P(AF2:AF6) -> 0.0022966062 | AG8: =_xlfn.STDEV.P(AG2:AG6) -> 0.014449581
A9: SNR (dB) | E9: =20*LOG10(E7/E8) -> 38.767319 | F9: =20*LOG10(F7/F8) -> 44.493198 | K9: =20*LOG10(K7/K8) -> 49.14397 | L9: =20*LOG10(L7/L8) -> 45.876857 | N9: =20*LOG10(N7/N8) -> 47.158116 | O9: =20*LOG10(O7/O8) -> 42.979247 | Q9: =20*LOG10(Q7/Q8) -> 44.912358 | R9: =20*LOG10(R7/R8) -> 43.349969 | T9: =20*LOG10(T7/T8) -> 53.574141 | U9: =20*LOG10(U7/U8) -> 41.708391 | W9: =20*LOG10(W7/W8) -> 46.912822 | X9: =20*LOG10(X7/X8) -> 38.018466 | Z9: =20*LOG10(Z7/Z8) -> 48.856549 | AA9: =20*LOG10(AA7/AA8) -> 39.226469 | AC9: =20*LOG10(AC7/AC8) -> 40.403279 | AD9: =20*LOG10(AD7/AD8) -> 37.130309 | AF9: =20*LOG10(AF7/AF8) -> 50.778398 | AG9: =20*LOG10(AG7/AG8) -> 33.555421
A10: Valor simulado | E10: =(0.000528043*2*1000) -> 1.056086 | F10: =(0.000527572*2*1000) -> 1.055144 | K10: 0.132 | L10: 0.1319 | N10: 1.0978 | O10: 1.0968 | Q10: 0.3057 | R10: 0.3055 | T10: 0.8306 | U10: 0.8299 | W10: 0.3057 | X10: 0.3055 | Z10: 0.8306 | AA10: 0.8299 | AC10: 0.3057 | AD10: 0.3055 | AF10: 0.8306 | AG10: 0.8299
A11: Razao de amplitudes medido (V/I) | K11: =K7/$E$7 -> 0.073389828 | L11: =L7/$F$7 -> 0.090372414 | N11: =N7/$E$7 -> 0.68251737 | O11: =O7/$F$7 -> 0.82907586 | Q11: =Q7/$E$7 -> 0.1883342 | R11: =R7/$F$7 -> 0.23038161 | T11: =T7/$E$7 -> 0.53236408 | U11: =U7/$F$7 -> 0.64785287 | W11: =W7/$E$7 -> 0.18826727 | X11: =X7/$F$7 -> 0.2301977 | Z11: =Z7/$E$7 -> 0.53142696 | AA11: =AA7/$F$7 -> 0.64251954 | AC11: =AC7/$E$7 -> 0.18688836 | AD11: =AD7/$F$7 -> 0.22701609 | AF11: =AF7/$E$7 -> 0.5317081 | AG11: =AG7/$F$7 -> 0.63269885
A12: Razao de amplitudes simulado (V/I) | K12: =K10/$E$10 -> 0.12498982 | L12: =L10/$F$10 -> 0.12500663 | N12: =N10/$E$10 -> 1.0394987 | O12: =O10/$F$10 -> 1.039479 | Q12: =Q10/$E$10 -> 0.28946506 | R12: =R10/$F$10 -> 0.28953394 | T12: =T10/$E$10 -> 0.78648898 | U12: =U10/$F$10 -> 0.78652772 | W12: =W10/$E$10 -> 0.28946506 | X12: =X10/$F$10 -> 0.28953394 | Z12: =Z10/$E$10 -> 0.78648898 | AA12: =AA10/$F$10 -> 0.78652772 | AC12: =AC10/$E$10 -> 0.28946506 | AD12: =AD10/$F$10 -> 0.28953394 | AF12: =AF10/$E$10 -> 0.78648898 | AG12: =AG10/$F$10 -> 0.78652772
A13: Acurácia | K13: =1-((ABS(K11-K12))/K12) -> 0.58716644 | L13: =1-((ABS(L11-L12))/L12) -> 0.72294094 | N13: =1-((ABS(N11-N12))/N12) -> 0.6565832 | O13: =1-((ABS(O11-O12))/O12) -> 0.79758791 | Q13: =1-((ABS(Q11-Q12))/Q12) -> 0.65062845 | R13: =1-((ABS(R11-R12))/R12) -> 0.79569811 | T13: =1-((ABS(T11-T12))/T12) -> 0.6768869 | U13: =1-((ABS(U11-U12))/U12) -> 0.82368728 | W13: =1-((ABS(W11-W12))/W12) -> 0.6503972 | X13: =1-((ABS(X11-X12))/X12) -> 0.79506292 | Z13: =1-((ABS(Z11-Z12))/Z12) -> 0.67569537 | AA13: =1-((ABS(AA11-AA12))/AA12) -> 0.81690642 | AC13: =1-((ABS(AC11-AC12))/AC12) -> 0.64563357 | AD13: =1-((ABS(AD11-AD12))/AD12) -> 0.7840742 | AF13: =1-((ABS(AF11-AF12))/AF12) -> 0.67605283 | AG13: =1-((ABS(AG11-AG12))/AG12) -> 0.80442029
A14: E2 conectado ao I1 e E1 conectado ao terra
B15: {=_xlfn._xlws.FILTER('Dado Bruto'!A:AF, ('Dado Bruto'!A:A=5) + ('Dado Bruto'!A:A=25) + ('Dado Bruto'!A:A=45)+ ('Dado Bruto'!A:A=65)+ ('Dado Bruto'!A:A=85), "Não encontrado")} -> 5 | C15: -> | D15: E91 | E15: 1.482 | F15: 1.1035 | G15: E92 | H15: 0 | I15: 0 | J15: E0 | K15: 0.8906 | L15: 0.806 | M15: E1 | N15: 0.1091 | O15: 0.1008 | P15: E2 | Q15: 0.9461 | R15: 0.8653 | S15: E3 | T15: 0.3736 | U15: 0.3443 | V15: E4 | W15: 0.887 | X15: 0.8132 | Y15: E5 | Z15: 0.3735 | AA15: 0.3431 | AB15: E6 | AC15: 0.8831 | AD15: 0.8104 | AE15: E7 | AF15: 0.3735 | AG15: 0.348
B16: 25 | C16: -> | D16: E91 | E16: 1.472 | F16: 1.1256 | G16: E92 | H16: 0 | I16: 0 | J16: E0 | K16: 0.8879 | L16: 0.8138 | M16: E1 | N16: 0.1091 | O16: 0.0998 | P16: E2 | Q16: 0.9482 | R16: 0.8688 | S16: E3 | T16: 0.3741 | U16: 0.3452 | V16: E4 | W16: 0.8885 | X16: 0.8156 | Y16: E5 | Z16: 0.3742 | AA16: 0.3443 | AB16: E6 | AC16: 0.8872 | AD16: 0.8135 | AE16: E7 | AF16: 0.3746 | AG16: 0.3454
B17: 45 | C17: -> | D17: E91 | E17: 1.5022 | F17: 1.0827 | G17: E92 | H17: 0 | I17: 0 | J17: E0 | K17: 0.8886 | L17: 0.8136 | M17: E1 | N17: 0.1097 | O17: 0.1009 | P17: E2 | Q17: 0.9466 | R17: 0.8674 | S17: E3 | T17: 0.3756 | U17: 0.3444 | V17: E4 | W17: 0.8881 | X17: 0.8158 | Y17: E5 | Z17: 0.3736 | AA17: 0.3437 | AB17: E6 | AC17: 0.8835 | AD17: 0.8112 | AE17: E7 | AF17: 0.375 | AG17: 0.3471
B18: 65 | C18: -> | D18: E91 | E18: 1.4662 | F18: 1.1118 | G18: E92 | H18: 0 | I18: 0 | J18: E0 | K18: 0.8888 | L18: 0.8144 | M18: E1 | N18: 0.1093 | O18: 0.1006 | P18: E2 | Q18: 0.9466 | R18: 0.8659 | S18: E3 | T18: 0.3741 | U18: 0.346 | V18: E4 | W18: 0.8866 | X18: 0.8122 | Y18: E5 | Z18: 0.3736 | AA18: 0.3444 | AB18: E6 | AC18: 0.8851 | AD18: 0.8129 | AE18: E7 | AF18: 0.3744 | AG18: 0.3525
B19: 85 | C19: -> | D19: E91 | E19: 1.5026 | F19: 1.0919 | G19: E92 | H19: 0 | I19: 0 | J19: E0 | K19: 0.888 | L19: 0.8121 | M19: E1 | N19: 0.1093 | O19: 0.101 | P19: E2 | Q19: 0.9521 | R19: 0.8733 | S19: E3 | T19: 0.3747 | U19: 0.3459 | V19: E4 | W19: 0.89 | X19: 0.8166 | Y19: E5 | Z19: 0.3733 | AA19: 0.3437 | AB19: E6 | AC19: 0.8836 | AD19: 0.81 | AE19: E7 | AF19: 0.3731 | AG19: 0.3474
A20: Média | E20: =AVERAGE(E15:E19) -> 1.485 | F20: =AVERAGE(F15:F19) -> 1.1031 | K20: =AVERAGE(K15:K19) -> 0.88878 | L20: =AVERAGE(L15:L19) -> 0.81198 | N20: =AVERAGE(N15:N19) -> 0.1093 | O20: =AVERAGE(O15:O19) -> 0.10062 | Q20: =AVERAGE(Q15:Q19) -> 0.94792 | R20: =AVERAGE(R15:R19) -> 0.86814 | T20: =AVERAGE(T15:T19) -> 0.37442 | U20: =AVERAGE(U15:U19) -> 0.34516 | W20: =AVERAGE(W15:W19) -> 0.88804 | X20: =AVERAGE(X15:X19) -> 0.81468 | Z20: =AVERAGE(Z15:Z19) -> 0.37364 | AA20: =AVERAGE(AA15:AA19) -> 0.34384 | AC20: =AVERAGE(AC15:AC19) -> 0.8845 | AD20: =AVERAGE(AD15:AD19) -> 0.8116 | AF20: =AVERAGE(AF15:AF19) -> 0.37412 | AG20: =AVERAGE(AG15:AG19) -> 0.34808
A21: STD | E21: =_xlfn.STDEV.P(E15:E19) -> 0.015080053 | F21: =_xlfn.STDEV.P(F15:F19) -> 0.014991331 | K21: =_xlfn.STDEV.P(K15:K19) -> 0.00097241966 | L21: =_xlfn.STDEV.P(L15:L19) -> 0.0030844124 | N21: =_xlfn.STDEV.P(N15:N19) -> 0.00021908902 | O21: =_xlfn.STDEV.P(O15:O19) -> 0.00043081318 | Q21: =_xlfn.STDEV.P(Q15:Q19) -> 0.002206717 | R21: =_xlfn.STDEV.P(R15:R19) -> 0.0028527881 | T21: =_xlfn.STDEV.P(T15:T19) -> 0.00068527367 | U21: =_xlfn.STDEV.P(U15:U19) -> 0.00071721684 | W21: =_xlfn.STDEV.P(W15:W19) -> 0.0012009996 | X21: =_xlfn.STDEV.P(X15:X19) -> 0.0016809521 | Z21: =_xlfn.STDEV.P(Z15:Z19) -> 0.00030066593 | AA21: =_xlfn.STDEV.P(AA15:AA19) -> 0.00047159304 | AC21: =_xlfn.STDEV.P(AC15:AC19) -> 0.0015112908 | AD21: =_xlfn.STDEV.P(AD15:AD19) -> 0.0013754999 | AF21: =_xlfn.STDEV.P(AF15:AF19) -> 0.00070823725 | AG21: =_xlfn.STDEV.P(AG15:AG19) -> 0.0023726778
A22: SNR (dB) | E22: =20*LOG10(E20/E21) -> 39.866472 | F22: =20*LOG10(F20/F21) -> 37.335494 | K22: =20*LOG10(K20/K21) -> 59.218811 | L22: =20*LOG10(L20/L21) -> 48.407458 | N22: =20*LOG10(N20/N21) -> 53.959991 | O22: =20*LOG10(O20/O21) -> 47.367907 | Q22: =20*LOG10(Q20/Q21) -> 52.660501 | R22: =20*LOG10(R20/R21) -> 49.666405 | T22: =20*LOG10(T20/T21) -> 54.7499 | U22: =20*LOG10(U20/U21) -> 53.6474 | W22: =20*LOG10(W20/W21) -> 57.377793 | X22: =20*LOG10(X20/X21) -> 53.708634 | Z22: =20*LOG10(Z20/Z21) -> 61.887383 | AA22: =20*LOG10(AA20/AA21) -> 57.25578 | AC22: =20*LOG10(AC20/AC21) -> 55.346996 | AD22: =20*LOG10(AD20/AD21) -> 55.417629 | AF22: =20*LOG10(AF20/AF21) -> 54.456643 | AG22: =20*LOG10(AG20/AG21) -> 43.328806
A23: Valor simulado | E23: =(0.000528123)*2*1000 -> 1.056246 | F23: =(0.000527607)*2*1000 -> 1.055214 | K23: 0.9242 | L23: 0.9233 | N23: 0.132 | O23: 0.1319 | Q23: 0.9997 | R23: 0.9988 | T23: 0.3993 | U23: 0.3989 | W23: 0.9242 | X23: 0.9233 | Z23: 0.3993 | AA23: 0.3989 | AC23: 0.9242 | AD23: 0.9233 | AF23: 0.3993 | AG23: 0.3989
A24: Razao de amplitudes medido (V/I) | K24: =K20/$E$20 -> 0.59850505 | L24: =L20/$F$20 -> 0.7360892 | N24: =N20/$E$20 -> 0.073602694 | O24: =O20/$F$20 -> 0.091215665 | Q24: =Q20/$E$20 -> 0.63832997 | R24: =R20/$F$20 -> 0.78700027 | T24: =T20/$E$20 -> 0.25213468 | U24: =U20/$F$20 -> 0.31290001 | W24: =W20/$E$20 -> 0.59800673 | X24: =X20/$F$20 -> 0.73853685 | Z24: =Z20/$E$20 -> 0.25160943 | AA24: =AA20/$F$20 -> 0.31170338 | AC24: =AC20/$E$20 -> 0.5956229 | AD24: =AD20/$F$20 -> 0.73574472 | AF24: =AF20/$E$20 -> 0.25193266 | AG24: =AG20/$F$20 -> 0.31554709
A25: Razao de amplitudes simulado (V/I) | K25: =K23/$E$23 -> 0.87498556 | L25: =L23/$F$23 -> 0.87498839 | N25: =N23/$E$23 -> 0.12497089 | O25: =O23/$F$23 -> 0.12499834 | Q25: =Q23/$E$23 -> 0.94646512 | R25: =R23/$F$23 -> 0.94653786 | T25: =T23/$E$23 -> 0.37803693 | U25: =U23/$F$23 -> 0.37802758 | W25: =W23/$E$23 -> 0.87498556 | X25: =X23/$F$23 -> 0.87498839 | Z25: =Z23/$E$23 -> 0.37803693 | AA25: =AA23/$F$23 -> 0.37802758 | AC25: =AC23/$E$23 -> 0.87498556 | AD25: =AD23/$F$23 -> 0.87498839 | AF25: =AF23/$E$23 -> 0.37803693 | AG25: =AG23/$F$23 -> 0.37802758
A26: Acurácia | K26: =1-((ABS(K24-K25))/K25) -> 0.68401706 | L26: =1-((ABS(L24-L25))/L25) -> 0.84125596 | N26: =1-((ABS(N24-N25))/N25) -> 0.58895872 | O26: =1-((ABS(O24-O25))/O25) -> 0.729735 | Q26: =1-((ABS(Q24-Q25))/Q25) -> 0.6744358 | R26: =1-((ABS(R24-R25))/R25) -> 0.83145145 | T26: =1-((ABS(T24-T25))/T25) -> 0.66695779 | U26: =1-((ABS(U24-U25))/U25) -> 0.8277174 | W26: =1-((ABS(W24-W25))/W25) -> 0.68344754 | X26: =1-((ABS(X24-X25))/X25) -> 0.84405331 | Z26: =1-((ABS(Z24-Z25))/Z25) -> 0.66556837 | AA26: =1-((ABS(AA24-AA25))/AA25) -> 0.82455195 | AC26: =1-((ABS(AC24-AC25))/AC25) -> 0.68072311 | AD26: =1-((ABS(AD24-AD25))/AD25) -> 0.84086226 | AF26: =1-((ABS(AF24-AF25))/AF25) -> 0.6664234 | AG26: =1-((ABS(AG24-AG25))/AG25) -> 0.83471976
A27: E3 conectado ao I1 e E2 conectado ao terra
B28: {=_xlfn._xlws.FILTER('Dado Bruto'!A:AF, ('Dado Bruto'!A:A=7) + ('Dado Bruto'!A:A=27) + ('Dado Bruto'!A:A=47)+ ('Dado Bruto'!A:A=67)+ ('Dado Bruto'!A:A=87), "Não encontrado")} -> 7 | C28: -> | D28: E91 | E28: 1.4674 | F28: 1.0915 | G28: E92 | H28: 0 | I28: 0 | J28: E0 | K28: 0.1908 | L28: 0.1782 | M28: E1 | N28: 0.7047 | O28: 0.6418 | P28: E2 | Q28: 0.1128 | R28: 0.1044 | S28: E3 | T28: 0.8381 | U28: 0.7652 | V28: E4 | W28: 0.1902 | X28: 0.1757 | Y28: E5 | Z28: 0.7036 | AA28: 0.6396 | AB28: E6 | AC28: 0.1892 | AD28: 0.1748 | AE28: E7 | AF28: 0.7044 | AG28: 0.6375
B29: 27 | C29: -> | D29: E91 | E29: 1.5179 | F29: 1.0718 | G29: E92 | H29: 0 | I29: 0 | J29: E0 | K29: 0.2195 | L29: 0.2067 | M29: E1 | N29: 0.7039 | O29: 0.6414 | P29: E2 | Q29: 0.1135 | R29: 0.1042 | S29: E3 | T29: 0.8378 | U29: 0.7639 | V29: E4 | W29: 0.19 | X29: 0.1748 | Y29: E5 | Z29: 0.7038 | AA29: 0.637 | AB29: E6 | AC29: 0.1908 | AD29: 0.1725 | AE29: E7 | AF29: 0.6957 | AG29: 0.6159
B30: 47 | C30: -> | D30: E91 | E30: 1.5107 | F30: 1.0764 | G30: E92 | H30: 0 | I30: 0 | J30: E0 | K30: 0.1905 | L30: 0.179 | M30: E1 | N30: 0.7055 | O30: 0.6407 | P30: E2 | Q30: 0.1135 | R30: 0.1047 | S30: E3 | T30: 0.8352 | U30: 0.7646 | V30: E4 | W30: 0.19 | X30: 0.1757 | Y30: E5 | Z30: 0.7047 | AA30: 0.6396 | AB30: E6 | AC30: 0.1903 | AD30: 0.1741 | AE30: E7 | AF30: 0.7041 | AG30: 0.6352
B31: 67 | C31: -> | D31: E91 | E31: 1.4722 | F31: 1.1097 | G31: E92 | H31: 0 | I31: 0 | J31: E0 | K31: 0.1899 | L31: 0.1729 | M31: E1 | N31: 0.7064 | O31: 0.6352 | P31: E2 | Q31: 0.1117 | R31: 0.1032 | S31: E3 | T31: 0.8371 | U31: 0.7612 | V31: E4 | W31: 0.1905 | X31: 0.1757 | Y31: E5 | Z31: 0.7038 | AA31: 0.6388 | AB31: E6 | AC31: 0.19 | AD31: 0.1752 | AE31: E7 | AF31: 0.7042 | AG31: 0.6346
B32: 87 | C32: -> | D32: E91 | E32: 1.5085 | F32: 1.0731 | G32: E92 | H32: 0 | I32: 0 | J32: E0 | K32: 0.1906 | L32: 0.1787 | M32: E1 | N32: 0.7034 | O32: 0.6413 | P32: E2 | Q32: 0.1134 | R32: 0.1046 | S32: E3 | T32: 0.8375 | U32: 0.7648 | V32: E4 | W32: 0.1907 | X32: 0.1763 | Y32: E5 | Z32: 0.7046 | AA32: 0.6407 | AB32: E6 | AC32: 0.1897 | AD32: 0.1751 | AE32: E7 | AF32: 0.7057 | AG32: 0.6371
A33: Média | E33: =AVERAGE(E28:E32) -> 1.49534 | F33: =AVERAGE(F28:F32) -> 1.0845 | K33: =AVERAGE(K28:K32) -> 0.19626 | L33: =AVERAGE(L28:L32) -> 0.1831 | N33: =AVERAGE(N28:N32) -> 0.70478 | O33: =AVERAGE(O28:O32) -> 0.64008 | Q33: =AVERAGE(Q28:Q32) -> 0.11298 | R33: =AVERAGE(R28:R32) -> 0.10422 | T33: =AVERAGE(T28:T32) -> 0.83714 | U33: =AVERAGE(U28:U32) -> 0.76394 | W33: =AVERAGE(W28:W32) -> 0.19028 | X33: =AVERAGE(X28:X32) -> 0.17564 | Z33: =AVERAGE(Z28:Z32) -> 0.7041 | AA33: =AVERAGE(AA28:AA32) -> 0.63914 | AC33: =AVERAGE(AC28:AC32) -> 0.19 | AD33: =AVERAGE(AD28:AD32) -> 0.17434 | AF33: =AVERAGE(AF28:AF32) -> 0.70282 | AG33: =AVERAGE(AG28:AG32) -> 0.63206
A34: STD | E34: =_xlfn.STDEV.P(E28:E32) -> 0.021138458 | F34: =_xlfn.STDEV.P(F28:F32) -> 0.014428444 | K34: =_xlfn.STDEV.P(K28:K32) -> 0.011623872 | L34: =_xlfn.STDEV.P(L28:L32) -> 0.012009829 | N34: =_xlfn.STDEV.P(N28:N32) -> 0.0010796296 | O34: =_xlfn.STDEV.P(O28:O32) -> 0.0024652789 | Q34: =_xlfn.STDEV.P(Q28:Q32) -> 0.0006910861 | R34: =_xlfn.STDEV.P(R28:R32) -> 0.00053814496 | T34: =_xlfn.STDEV.P(T28:T32) -> 0.0010248902 | U34: =_xlfn.STDEV.P(U28:U32) -> 0.0014333178 | W34: =_xlfn.STDEV.P(W28:W32) -> 0.00027856777 | X34: =_xlfn.STDEV.P(X28:X32) -> 0.00048 | Z34: =_xlfn.STDEV.P(Z28:Z32) -> 0.00045607017 | AA34: =_xlfn.STDEV.P(AA28:AA32) -> 0.0012289833 | AC34: =_xlfn.STDEV.P(AC28:AC32) -> 0.00054037024 | AD34: =_xlfn.STDEV.P(AD28:AD32) -> 0.00099719607 | AF34: =_xlfn.STDEV.P(AF28:AF32) -> 0.0036063278 | AG34: =_xlfn.STDEV.P(AG28:AG32) -> 0.0081541646
A35: SNR (dB) | E35: =20*LOG10(E33/E34) -> 36.993333 | F35: =20*LOG10(F33/F34) -> 37.520201 | K35: =20*LOG10(K33/K34) -> 24.54962 | L35: =20*LOG10(L33/L34) -> 23.66303 | N35: =20*LOG10(N33/N34) -> 56.295576 | O35: =20*LOG10(O33/O34) -> 48.287364 | Q35: =20*LOG10(Q33/Q34) -> 44.269388 | R35: =20*LOG10(R33/R34) -> 45.741036 | T35: =20*LOG10(T33/T34) -> 58.242415 | U35: =20*LOG10(U33/U34) -> 54.534335 | W35: =20*LOG10(W33/W34) -> 56.689246 | X35: =20*LOG10(X33/X34) -> 51.267644 | Z35: =20*LOG10(Z33/Z34) -> 63.772054 | AA35: =20*LOG10(AA33/AA34) -> 54.321 | AC35: =20*LOG10(AC33/AC34) -> 50.921244 | AD35: =20*LOG10(AD33/AD34) -> 44.85233 | AF35: =20*LOG10(AF33/AF34) -> 45.795578 | AG35: =20*LOG10(AG33/AG34) -> 37.787577
A36: Valor simulado | E36: =(0.000528246)*2*1000 -> 1.056492 | F36: =(0.000527663)*2*1000 -> 1.055326 | K36: 0.2076 | L36: 0.2074 | N36: 0.7327 | O36: 0.7319 | Q36: 0.132 | R36: 0.1319 | T36: 0.8473 | U36: 0.8464 | W36: 0.2076 | X36: 0.2074 | Z36: 0.7327 | AA36: 0.7319 | AC36: 0.2076 | AD36: 0.2074 | AF36: 0.7327 | AG36: 0.7319
A37: Razao de amplitudes medido (V/I) | K37: =K33/$E$33 -> 0.13124774 | L37: =L33/$F$33 -> 0.16883356 | N37: =N33/$E$33 -> 0.47131756 | O37: =O33/$F$33 -> 0.59020747 | Q37: =Q33/$E$33 -> 0.075554723 | R37: =R33/$F$33 -> 0.096099585 | T37: =T33/$E$33 -> 0.55983255 | U37: =U33/$F$33 -> 0.70441678 | W37: =W33/$E$33 -> 0.12724865 | X37: =X33/$F$33 -> 0.16195482 | Z37: =Z33/$E$33 -> 0.47086281 | AA37: =AA33/$F$33 -> 0.58934071 | AC37: =AC33/$E$33 -> 0.1270614 | AD37: =AD33/$F$33 -> 0.16075611 | AF37: =AF33/$E$33 -> 0.47000682 | AG37: =AG33/$F$33 -> 0.58281236
A38: Razao de amplitudes simulado (V/I) | K38: =K36/$E$36 -> 0.19649936 | L38: =L36/$F$36 -> 0.19652695 | N38: =N36/$E$36 -> 0.69352158 | O38: =O36/$F$36 -> 0.69352977 | Q38: =Q36/$E$36 -> 0.12494179 | R38: =R36/$F$36 -> 0.12498508 | T38: =T36/$E$36 -> 0.80199377 | U38: =U36/$F$36 -> 0.80202705 | W38: =W36/$E$36 -> 0.19649936 | X38: =X36/$F$36 -> 0.19652695 | Z38: =Z36/$E$36 -> 0.69352158 | AA38: =AA36/$F$36 -> 0.69352977 | AC38: =AC36/$E$36 -> 0.19649936 | AD38: =AD36/$F$36 -> 0.19652695 | AF38: =AF36/$E$36 -> 0.69352158 | AG38: =AG36/$F$36 -> 0.69352977
A39: Acurácia | F39: =1-((ABS(F36-F33))/F33) -> 0.97309912 | K39: =1-((ABS(K37-K38))/K38) -> 0.66792963 | L39: =1-((ABS(L37-L38))/L38) -> 0.85908606 | N39: =1-((ABS(N37-N38))/N38) -> 0.67960043 | O39: =1-((ABS(O37-O38))/O38) -> 0.85101966 | Q39: =1-((ABS(Q37-Q38))/Q38) -> 0.6047194 | R39: =1-((ABS(R37-R38))/R38) -> 0.76888848 | T39: =1-((ABS(T37-T38))/T38) -> 0.69805099 | U39: =1-((ABS(U37-U38))/U38) -> 0.87829554 | W39: =1-((ABS(W37-W38))/W38) -> 0.64757795 | X39: =1-((ABS(X37-X38))/X38) -> 0.82408452 | Z39: =1-((ABS(Z37-Z38))/Z38) -> 0.67894472 | AA39: =1-((ABS(AA37-AA38))/AA38) -> 0.84976988 | AC39: =1-((ABS(AC37-AC38))/AC38) -> 0.64662503 | AD39: =1-((ABS(AD37-AD38))/AD38) -> 0.81798506 | AF39: =1-((ABS(AF37-AF38))/AF38) -> 0.67771045 | AG39: =1-((ABS(AG37-AG38))/AG38) -> 0.84035665
A41: E4 conectado ao I1 e E3 conectado ao terra
...

Sheet Sheet1

Sheet CONFIGURACAO

Sheet Acurácia
A1: CORRENTE
A2: Média | F2: 1.2322 | G2: 1.35504
A3: Valor simulado | F3: 1.056 | G3: 1.0528
A4: Acurácia | F4: 0.83314394 | G4: 0.71291793
A6: E1 conectado ao I1 e E0 conectado ao terra | F6: TERRA | I6: INJECAO CORRENTE | L6: I - A | O6: I - B | R6: I - A | U6: I - B | X6: I - A | AA6: I - B
A7: Média | F7: 0.10584 | G7: 0.1081 | I7: 0.97596 | J7: 0.9943 | L7: 0.27326 | M7: 0.27846 | O7: 0.77508 | P7: 0.78904 | R7: 0.27466 | S7: 0.27906 | U7: 0.77774 | V7: 0.78914 | X7: 0.27578 | Y7: 0.2795 | AA7: 0.77658 | AB7: 0.78886 | AD7: 0.27456667 | AF7: 0.27900667
A8: Valor simulado | F8: 0.132 | G8: 0.1316 | I8: 1.0977 | J8: 1.0943 | L8: 0.3057 | M8: 0.3048 | O8: 0.8305 | P8: 0.828 | R8: 0.3057 | S8: 0.3048 | U8: 0.8305 | V8: 0.828 | X8: 0.3057 | Y8: 0.3048 | AA8: 0.8305 | AB8: 0.828
A9: Acurácia | F9: 0.75283447 | G9: 0.7826087 | I9: 0.87526128 | J9: 0.89942673 | L9: 0.88128522 | M9: 0.90540832 | O9: 0.9284977 | P9: 0.95062354 | R9: 0.88698755 | S9: 0.90776177 | U9: 0.93216242 | V9: 0.95075652 | X9: 0.89150772 | Y9: 0.90948122 | AA9: 0.93056736 | AB9: 0.9503841
A11: E2 conectado ao I1 e E1 conectado ao terra | F11: I - B | I11: TERRA | L11: INJECAO CORRENTE | O11: I - A | R11: I - B | U11: I - A | X11: I - B | AA11: I - A
A12: Média | F12: 0.8647 | G12: 0.87924 | I12: 0.10562 | J12: 0.1072 | L12: 0.92578 | M12: 0.94158 | O12: 0.36312 | P12: 0.36964 | R12: 0.86636 | S12: 0.88176 | U12: 0.36426 | V12: 0.36892 | X12: 0.8627 | Y12: 0.87702 | AA12: 0.36292 | AB12: 0.37054
A13: Valor simulado | F13: 0.9241 | G13: 0.9213 | I13: 0.132 | J13: 0.1316 | L13: 0.9996 | M13: 0.9965 | O13: 0.3992 | P13: 0.398 | R13: 0.9241 | S13: 0.9213 | U13: 0.3992 | V13: 0.398 | X13: 0.9241 | Y13: 0.9213 | AA13: 0.3992 | AB13: 0.398
A14: Acurácia | F14: 0.93130566 | G14: 0.95216323 | I14: 0.7502367 | J14: 0.77238806 | L14: 0.92026183 | M14: 0.94167251 | O14: 0.90063891 | P14: 0.9232767 | R14: 0.93335334 | S14: 0.95515787 | U14: 0.9040795 | V14: 0.92117532 | X14: 0.9288281 | Y14: 0.94951084 | AA14: 0.90003307 | AB14: 0.92589194
A16: E3 conectado ao I1 e E2 conectado ao terra | L16: TERRA | O16: INJECAO CORRENTE | R16: I +1 | U16: I +2
A17: Média | F17: 0.18406 | G17: 0.18668 | I17: 0.68524 | J17: 0.69704 | L17: 0.10554 | M17: 0.1077 | O17: 0.80146 | P17: 0.81348 | R17: 0.18294 | S17: 0.18676 | U17: 0.68474 | V17: 0.69808 | X17: 0.1825 | Y17: 0.18572 | AA17: 0.6854 | AB17: 0.69704
A18: Valor simulado | F18: 0.2076 | G18: 0.2069 | I18: 0.7326 | J18: 0.7303 | L18: 0.132 | M18: 0.1316 | O18: 0.8472 | P18: 0.8446 | R18: 0.2076 | S18: 0.2069 | U18: 0.7326 | V18: 0.7303 | X18: 0.2076 | Y18: 0.2069 | AA18: 0.7326 | AB18: 0.7303
A19: Acurácia | F19: 0.87210692 | G19: 0.89168631 | I19: 0.93088553 | J19: 0.95228394 | L19: 0.74928937 | M19: 0.77808728 | O19: 0.94292915 | P19: 0.9617446 | R19: 0.86520171 | S19: 0.89216106 | U19: 0.93010486 | V19: 0.95384483 | X19: 0.86246575 | Y19: 0.88595736 | AA19: 0.9311351 | AB19: 0.95228394
A21: E4 conectado ao I1 e E3 conectado ao terra | O21: TERRA | R21: INJECAO CORRENTE | U21: I +1 | X21: I +2
A22: Média | F22: 0.725 | G22: 0.73846 | I22: 0.22144 | J22: 0.2256 | L22: 0.72156 | M22: 0.73626 | O22: 0.10824 | P22: 0.11012 | R22: 0.86212 | S22: 0.87736 | U22: 0.22168 | V22: 0.22612 | X22: 0.72378 | Y22: 0.736 | AA22: 0.22246 | AB22: 0.2246
A23: Valor simulado | F23: 0.7716 | G23: 0.7693 | I23: 0.2466 | J23: 0.2459 | L23: 0.7716 | M23: 0.7693 | O23: 0.132 | P23: 0.1316 | R23: 0.9094 | S23: 0.9067 | U23: 0.2466 | V23: 0.2459 | X23: 0.7716 | Y23: 0.7693 | AA23: 0.2466 | AB23: 0.2459
A24: Acurácia | F24: 0.93572414 | G24: 0.95823741 | I24: 0.88638006 | J24: 0.91001773 | L24: 0.93065026 | M24: 0.95512455 | O24: 0.7804878 | P24: 0.80494007 | R24: 0.94515845 | S24: 0.96655877 | U24: 0.88758571 | V24: 0.91252432 | X24: 0.9339302 | Y24: 0.95475543 | AA24: 0.89148611 | AB24: 0.90516474
A26: E5 conectado ao I1 e E4 conectado ao terra | R26: TERRA | U26: INJECAO CORRENTE | X26: I +1 | AA26: I +2
A27: Média | F27: 0.24084 | G27: 0.24518 | I27: 0.74202 | J27: 0.75356 | L27: 0.23818 | M27: 0.24296 | O27: 0.74232 | P27: 0.75492 | R27: 0.10338 | S27: 0.10442 | U27: 0.94406 | V27: 0.95938 | X27: 0.2408 | Y27: 0.24358 | AA27: 0.74218 | AB27: 0.75264
A28: Valor simulado | F28: 0.2698 | G28: 0.269 | I28: 0.7947 | J28: 0.7922 | L28: 0.2698 | M28: 0.269 | O28: 0.7947 | P28: 0.7922 | R28: 0.132 | S28: 0.1316 | U28: 1.0407 | V28: 1.0375 | X28: 0.2698 | Y28: 0.269 | AA28: 0.7947 | AB28: 0.7922
A29: Acurácia | F29: 0.87975419 | G29: 0.90284689 | I29: 0.92900461 | J29: 0.94872339 | L29: 0.86724326 | M29: 0.89282186 | O29: 0.92943744 | P29: 0.95061728 | R29: 0.72315728 | S29: 0.73970504 | U29: 0.89763362 | V29: 0.91857241 | X29: 0.87956811 | Y29: 0.89564004 | AA29: 0.9292355 | AB29: 0.94743835
A31: E6 conectado ao I1 e E5 conectado ao terra | F31: I +2 | U31: TERRA | X31: INJECAO CORRENTE | AA31: I +1
A32: Média | F32: 0.842 | G32: 0.85752 | I32: 0.33806 | J32: 0.3436 | L32: 0.83886 | M32: 0.85436 | O32: 0.33928 | P32: 0.34442 | R32: 0.84346 | S32: 0.85634 | U32: 0.10302 | V32: 0.105 | X32: 0.89702 | Y32: 0.91232 | AA32: 0.33734 | AB32: 0.34456
A33: Valor simulado | F33: 0.903 | G33: 0.9003 | I33: 0.3781 | J33: 0.377 | L33: 0.903 | M33: 0.9003 | O33: 0.3781 | P33: 0.377 | R33: 0.903 | S33: 0.9003 | U33: 0.132 | V33: 0.1316 | X33: 0.9543 | Y33: 0.9513 | AA33: 0.3781 | AB33: 0.377
A34: Acurácia | F34: 0.92755344 | G34: 0.95011195 | I34: 0.88155949 | J34: 0.90279395 | L34: 0.92353909 | M34: 0.94622876 | O34: 0.88558123 | P34: 0.90540619 | R34: 0.92940981 | S34: 0.94866525 | U34: 0.7186954 | V34: 0.74666667 | X34: 0.93614412 | Y34: 0.95727376 | AA34: 0.87917235 | AB34: 0.90585094
A36: E7 conectado ao I1 e E6 conectado ao terra | F36: I +1 | I36: I +2 | X36: TERRA | AA36: INJECAO CORRENTE
A37: Média | F37: 0.17614 | G37: 0.17922 | I37: 0.67844 | J37: 0.6898 | L37: 0.17542 | M37: 0.17842 | O37: 0.67908 | P37: 0.69058 | R37: 0.17544 | S37: 0.17812 | U37: 0.67804 | V37: 0.68964 | X37: 0.1035 | Y37: 0.10482 | AA37: 0.96664 | AB37: 0.9868
A38: Valor simulado | F38: 0.1833 | G38: 0.1828 | I38: 0.7085 | J38: 0.7063 | L38: 0.1833 | M38: 0.1828 | O38: 0.7085 | P38: 0.7063 | R38: 0.1833 | S38: 0.1828 | U38: 0.7085 | V38: 0.7063 | X38: 0.1321 | Y38: 0.1317 | AA38: 0.7084 | AB38: 0.7063
A39: Acurácia | F39: 0.95935052 | G39: 0.98002455 | I39: 0.95569247 | J39: 0.97608002 | L39: 0.95507924 | M39: 0.97545118 | O39: 0.95667668 | P39: 0.97723653 | R39: 0.95519836 | S39: 0.97372558 | U39: 0.9550764 | V39: 0.97584247 | X39: 0.7236715 | Y39: 0.74356039 | AA39: 0.7328478 | AB39: 0.71574787
A41: E0 conectado ao I1 e E7 conectado ao terra | F41: INJECAO CORRENTE | I41: I +1 | L41: I +2 | AA41: TERRA
A42: Média | F42: 1.01556 | G42: 1.04206 | I42: 0.44752 | J42: 0.4555 | L42: 0.91928 | M42: 0.93628 | O42: 0.44872 | P42: 0.45522 | R42: 0.92172 | S42: 0.93906 | U42: 0.44764 | V42: 0.45558 | X42: 0.91874 | Y42: 0.93612 | AA42: 0.103 | AB42: 0.10546
A43: Valor simulado | F43: 1.1894 | G43: 1.1858 | I43: 0.491 | J43: 0.4895 | L43: 1.0157 | M43: 1.0126 | O43: 0.491 | P43: 0.4895 | R43: 1.0157 | S43: 1.0126 | U43: 0.491 | V43: 0.4895 | X43: 1.0157 | Y43: 1.0126 | AA43: 0.132 | AB43: 0.1316
A44: Acurácia | F44: 0.82882351 | G44: 0.86206169 | I44: 0.90284233 | J44: 0.92535675 | L44: 0.89511357 | M44: 0.91848592 | O44: 0.90577643 | P44: 0.92469575 | R44: 0.89803845 | S44: 0.92168765 | U44: 0.90313645 | V44: 0.92554546 | X44: 0.89446416 | Y44: 0.91830107 | AA44: 0.7184466 | AB44: 0.75213351
C50: E1-I e E0 - T | D50: E2-I e E1 - T | E50: E3-I e E2- T | F50: E4-I e E3- T | G50: E5-I e E4- T | H50: E6-I e E5- T | I50: E7-I e E6- T | J50: E0-I e E7- T
A51: TERRA | B51: FREQ 1
B52: FREQ 2
A53: INJECAO CORRENTE | B53: FREQ 1
...

Sheet DP
A1: CORRENTE
B2: 1 | C2: -> | D2: 0 | E2: E91 | F2: 1.2126 | G2: 1.3916 | H2: E92 | I2: 0 | J2: 0 | K2: 0 | L2: 0 | M2: 0 | N2: 0 | O2: 0 | P2: 0 | Q2: 0 | R2: 0 | S2: 0 | T2: 0 | U2: 0 | V2: 0 | W2: 0 | X2: 0 | Y2: 0 | Z2: 0 | AA2: 0 | AB2: 0
B3: 21 | C3: -> | D3: 0 | E3: E91 | F3: 1.2247 | G3: 1.3672 | H3: E92 | I3: 0 | J3: 0 | K3: 0 | L3: 0 | M3: 0 | N3: 0 | O3: 0 | P3: 0 | Q3: 0 | R3: 0 | S3: 0 | T3: 0 | U3: 0 | V3: 0 | W3: 0 | X3: 0 | Y3: 0 | Z3: 0 | AA3: 0 | AB3: 0
B4: 41 | C4: -> | D4: 0 | E4: E91 | F4: 1.2406 | G4: 1.3395 | H4: E92 | I4: 0 | J4: 0 | K4: 0 | L4: 0 | M4: 0 | N4: 0 | O4: 0 | P4: 0 | Q4: 0 | R4: 0 | S4: 0 | T4: 0 | U4: 0 | V4: 0 | W4: 0 | X4: 0 | Y4: 0 | Z4: 0 | AA4: 0 | AB4: 0
B5: 61 | C5: -> | D5: 0 | E5: E91 | F5: 1.2489 | G5: 1.328 | H5: E92 | I5: 0 | J5: 0 | K5: 0 | L5: 0 | M5: 0 | N5: 0 | O5: 0 | P5: 0 | Q5: 0 | R5: 0 | S5: 0 | T5: 0 | U5: 0 | V5: 0 | W5: 0 | X5: 0 | Y5: 0 | Z5: 0 | AA5: 0 | AB5: 0
B6: 81 | C6: -> | D6: 0 | E6: E91 | F6: 1.2342 | G6: 1.3489 | H6: E92 | I6: 0 | J6: 0 | K6: 0 | L6: 0 | M6: 0 | N6: 0 | O6: 0 | P6: 0 | Q6: 0 | R6: 0 | S6: 0 | T6: 0 | U6: 0 | V6: 0 | W6: 0 | X6: 0 | Y6: 0 | Z6: 0 | AA6: 0 | AB6: 0
A7: Média | F7: 1.2322 | G7: 1.35504
A8: STD | F8: 0.012600476 | G8: 0.022337645
A9: SNR (dB) | F9: 39.805885 | G9: 35.658294
A10: Valor simulado | F10: 1.056 | G10: 1.0528
A11: Acurácia | F11: 0.83314394 | G11: 0.71291793
A13: E1 conectado ao I1 e E0 conectado ao terra
B14: 3 | C14: -> | D14: 0 | E14: E0 | F14: 0.1058 | G14: 0.1079 | H14: E1 | I14: 0.9861 | J14: 0.9986 | K14: E2 | L14: 0.274 | M14: 0.2784 | N14: E3 | O14: 0.7782 | P14: 0.7908 | Q14: E4 | R14: 0.2755 | S14: 0.2791 | T14: E5 | U14: 0.7769 | V14: 0.7908 | W14: E6 | X14: 0.2756 | Y14: 0.2779 | Z14: E7 | AA14: 0.7783 | AB14: 0.79 | AD14: E2 E4 E6 | AE14: DP | AF14: E2 E4 E6 | AG14: DP | AI14: E3 E5 E7 | AJ14: DP | AK14: E3 E5 E7 | AL14: DP
B15: 23 | C15: -> | D15: 0 | E15: E0 | F15: 0.1057 | G15: 0.1075 | H15: E1 | I15: 0.9815 | J15: 0.9933 | K15: E2 | L15: 0.2714 | M15: 0.2776 | N15: E3 | O15: 0.7755 | P15: 0.7856 | Q15: E4 | R15: 0.2747 | S15: 0.2765 | T15: E5 | U15: 0.7795 | V15: 0.7866 | W15: E6 | X15: 0.2737 | Y15: 0.276 | Z15: E7 | AA15: 0.7773 | AB15: 0.7831 | AD15: 0.27326667 | AF15: 0.2767
B16: 43 | C16: -> | D16: 0 | E16: E0 | F16: 0.1063 | G16: 0.1081 | H16: E1 | I16: 0.9792 | J16: 0.9998 | K16: E2 | L16: 0.2734 | M16: 0.2783 | N16: E3 | O16: 0.7775 | P16: 0.7915 | Q16: E4 | R16: 0.2748 | S16: 0.2794 | T16: E5 | U16: 0.7774 | V16: 0.7895 | W16: E6 | X16: 0.2738 | Y16: 0.279 | Z16: E7 | AA16: 0.7764 | AB16: 0.789 | AD16: 0.274 | AF16: 0.2789
B17: 63 | C17: -> | D17: 0 | E17: E0 | F17: 0.1049 | G17: 0.1091 | H17: E1 | I17: 0.9661 | J17: 0.9886 | K17: E2 | L17: 0.2739 | M17: 0.2789 | N17: E3 | O17: 0.772 | P17: 0.7879 | Q17: E4 | R17: 0.2733 | S17: 0.2812 | T17: E5 | U17: 0.7778 | V17: 0.7886 | W17: E6 | X17: 0.2723 | Y17: 0.2788 | Z17: E7 | AA17: 0.7744 | AB17: 0.7886 | AD17: 0.27316667 | AF17: 0.27963333
B18: 83 | C18: -> | D18: 0 | E18: E0 | F18: 0.1065 | G18: 0.1079 | H18: E1 | I18: 0.9669 | J18: 0.9912 | K18: E2 | L18: 0.2736 | M18: 0.2791 | N18: E3 | O18: 0.7722 | P18: 0.7894 | Q18: E4 | R18: 0.275 | S18: 0.2791 | T18: E5 | U18: 0.7771 | V18: 0.7902 | W18: E6 | X18: 0.2835 | Y18: 0.2858 | Z18: E7 | AA18: 0.7765 | AB18: 0.7936 | AD18: 0.27736667 | AF18: 0.28133333
A19: Média | F19: 0.10584 | G19: 0.1081 | I19: 0.97596 | J19: 0.9943 | L19: 0.27326 | M19: 0.27846 | O19: 0.77508 | P19: 0.78904 | R19: 0.27466 | S19: 0.27906 | U19: 0.77774 | V19: 0.78914 | X19: 0.27578 | Y19: 0.2795 | AA19: 0.77658 | AB19: 0.78886 | AD19: 0.27456667 | AF19: 0.27900667
A20: STD | F20: 0.00055713553 | G20: 0.00053665631 | I20: 0.0080412934 | J20: 0.0042857905 | L20: 0.00095414884 | M20: 0.00052383203 | O20: 0.0025902896 | P20: 0.0021171679 | R20: 0.00073375745 | S20: 0.0015001333 | U20: 0.0009308061 | V20: 0.0014664242 | X20: 0.0039997 | Y20: 0.0033238532 | AA20: 0.0012859238 | AB20: 0.0033773362
A21: SNR (dB) | F21: 45.573779 | G21: 46.082589 | I21: 41.682122 | J21: 47.30973 | L21: 49.139199 | M21: 54.511415 | O21: 49.519964 | P21: 51.426874 | R21: 51.464858 | S21: 45.391355 | U21: 58.439504 | V21: 54.617889 | X21: 36.770707 | Y21: 38.4948 | AA21: 55.619419 | AB21: 47.368513
A22: Valor simulado | F22: 0.132 | G22: 0.1316 | I22: 1.0977 | J22: 1.0943 | L22: 0.3057 | M22: 0.3048 | O22: 0.8305 | P22: 0.828 | R22: 0.3057 | S22: 0.3048 | U22: 0.8305 | V22: 0.828 | X22: 0.3057 | Y22: 0.3048 | AA22: 0.8305 | AB22: 0.828
A23: Acurácia | F23: 0.75283447 | G23: 0.7826087 | I23: 0.87526128 | J23: 0.89942673 | L23: 0.88128522 | M23: 0.90540832 | O23: 0.9284977 | P23: 0.95062354 | R23: 0.88698755 | S23: 0.90776177 | U23: 0.93216242 | V23: 0.95075652 | X23: 0.89150772 | Y23: 0.90948122 | AA23: 0.93056736 | AB23: 0.9503841
A25: E2 conectado ao I1 e E1 conectado ao terra
B26: 5 | C26: -> | D26: 0 | E26: E0 | F26: 0.8631 | G26: 0.8778 | H26: E1 | I26: 0.1055 | J26: 0.1067 | K26: E2 | L26: 0.93 | M26: 0.943 | N26: E3 | O26: 0.3624 | P26: 0.3663 | Q26: E4 | R26: 0.8737 | S26: 0.8859 | T26: E5 | U26: 0.3634 | V26: 0.3683 | W26: E6 | X26: 0.8635 | Y26: 0.8789 | Z26: E7 | AA26: 0.3633 | AB26: 0.3677
B27: 25 | C27: -> | D27: 0 | E27: E0 | F27: 0.8674 | G27: 0.8823 | H27: E1 | I27: 0.1058 | J27: 0.1078 | K27: E2 | L27: 0.9337 | M27: 0.9478 | N27: E3 | O27: 0.363 | P27: 0.3718 | Q27: E4 | R27: 0.8682 | S27: 0.883 | T27: E5 | U27: 0.3637 | V27: 0.3684 | W27: E6 | X27: 0.8647 | Y27: 0.8789 | Z27: E7 | AA27: 0.3621 | AB27: 0.3743
B28: 45 | C28: -> | D28: 0 | E28: E0 | F28: 0.8653 | G28: 0.8796 | H28: E1 | I28: 0.1057 | J28: 0.1065 | K28: E2 | L28: 0.9272 | M28: 0.9448 | N28: E3 | O28: 0.3632 | P28: 0.3713 | Q28: E4 | R28: 0.863 | S28: 0.882 | T28: E5 | U28: 0.3662 | V28: 0.3707 | W28: E6 | X28: 0.8634 | Y28: 0.8757 | Z28: E7 | AA28: 0.3558 | AB28: 0.3706
B29: 65 | C29: -> | D29: 0 | E29: E0 | F29: 0.865 | G29: 0.8798 | H29: E1 | I29: 0.1055 | J29: 0.1077 | K29: E2 | L29: 0.9225 | M29: 0.9394 | N29: E3 | O29: 0.3641 | P29: 0.3696 | Q29: E4 | R29: 0.8664 | S29: 0.8804 | T29: E5 | U29: 0.3649 | V29: 0.3686 | W29: E6 | X29: 0.8627 | Y29: 0.8776 | Z29: E7 | AA29: 0.3698 | AB29: 0.3709
B30: 85 | C30: -> | D30: 0 | E30: E0 | F30: 0.8627 | G30: 0.8767 | H30: E1 | I30: 0.1056 | J30: 0.1073 | K30: E2 | L30: 0.9155 | M30: 0.9329 | N30: E3 | O30: 0.3629 | P30: 0.3692 | Q30: E4 | R30: 0.8605 | S30: 0.8775 | T30: E5 | U30: 0.3631 | V30: 0.3686 | W30: E6 | X30: 0.8592 | Y30: 0.874 | Z30: E7 | AA30: 0.3636 | AB30: 0.3692
A31: Média | F31: 0.8647 | G31: 0.87924 | I31: 0.10562 | J31: 0.1072 | L31: 0.92578 | M31: 0.94158 | O31: 0.36312 | P31: 0.36964 | R31: 0.86636 | S31: 0.88176 | U31: 0.36426 | V31: 0.36892 | X31: 0.8627 | Y31: 0.87702 | AA31: 0.36292 | AB31: 0.37054
A32: STD | F32: 0.0016911535 | G32: 0.0019147846 | I32: 0.00011661904 | J32: 0.00052153619 | L32: 0.0063085339 | M32: 0.0051218747 | O32: 0.00055641711 | P32: 0.0019376274 | R32: 0.0045363421 | S32: 0.0027832355 | U32: 0.0011464729 | V32: 0.00089755223 | X32: 0.0018644034 | Y32: 0.0019114392 | AA32: 0.0044566355 | AB32: 0.0021969069
A33: SNR (dB) | F33: 54.173649 | G33: 53.23975 | I33: 59.139534 | J33: 46.258207 | L33: 43.331587 | M33: 45.288566 | O33: 56.292994 | P33: 45.610174 | R33: 45.619852 | S33: 50.016009 | U33: 50.040954 | V33: 52.277449 | X33: 53.306398 | Y33: 53.23298 | AA33: 38.216076 | AB33: 44.540469
A34: Valor simulado | F34: 0.9241 | G34: 0.9213 | I34: 0.132 | J34: 0.1316 | L34: 0.9996 | M34: 0.9965 | O34: 0.3992 | P34: 0.398 | R34: 0.9241 | S34: 0.9213 | U34: 0.3992 | V34: 0.398 | X34: 0.9241 | Y34: 0.9213 | AA34: 0.3992 | AB34: 0.398
A35: Acurácia | F35: 0.93130566 | G35: 0.95216323 | I35: 0.7502367 | J35: 0.77238806 | L35: 0.92026183 | M35: 0.94167251 | O35: 0.90063891 | P35: 0.9232767 | R35: 0.93335334 | S35: 0.95515787 | U35: 0.9040795 | V35: 0.92117532 | X35: 0.9288281 | Y35: 0.94951084 | AA35: 0.90003307 | AB35: 0.92589194
A37: E3 conectado ao I1 e E2 conectado ao terra
B38: 7 | C38: -> | D38: 0 | E38: E0 | F38: 0.1859 | G38: 0.1864 | H38: E1 | I38: 0.6855 | J38: 0.6964 | K38: E2 | L38: 0.1053 | M38: 0.1075 | N38: E3 | O38: 0.7991 | P38: 0.8103 | Q38: E4 | R38: 0.1832 | S38: 0.1876 | T38: E5 | U38: 0.6844 | V38: 0.6963 | W38: E6 | X38: 0.1824 | Y38: 0.186 | Z38: E7 | AA38: 0.6877 | AB38: 0.6981
B39: 27 | C39: -> | D39: 0 | E39: E0 | F39: 0.1836 | G39: 0.1862 | H39: E1 | I39: 0.6849 | J39: 0.6977 | K39: E2 | L39: 0.1058 | M39: 0.1074 | N39: E3 | O39: 0.8015 | P39: 0.8138 | Q39: E4 | R39: 0.1834 | S39: 0.1861 | T39: E5 | U39: 0.6841 | V39: 0.697 | W39: E6 | X39: 0.1825 | Y39: 0.1858 | Z39: E7 | AA39: 0.6855 | AB39: 0.6954
B40: 47 | C40: -> | D40: 0 | E40: E0 | F40: 0.183 | G40: 0.1864 | H40: E1 | I40: 0.6865 | J40: 0.6966 | K40: E2 | L40: 0.1058 | M40: 0.108 | N40: E3 | O40: 0.8005 | P40: 0.8136 | Q40: E4 | R40: 0.1829 | S40: 0.1862 | T40: E5 | U40: 0.6862 | V40: 0.6982 | W40: E6 | X40: 0.1822 | Y40: 0.1853 | Z40: E7 | AA40: 0.6835 | AB40: 0.698
B41: 67 | C41: -> | D41: 0 | E41: E0 | F41: 0.1837 | G41: 0.1871 | H41: E1 | I41: 0.6849 | J41: 0.6966 | K41: E2 | L41: 0.1045 | M41: 0.1078 | N41: E3 | O41: 0.7998 | P41: 0.8142 | Q41: E4 | R41: 0.1824 | S41: 0.187 | T41: E5 | U41: 0.686 | V41: 0.6978 | W41: E6 | X41: 0.1825 | Y41: 0.1859 | Z41: E7 | AA41: 0.6828 | AB41: 0.6963
B42: 87 | C42: -> | D42: 0 | E42: E0 | F42: 0.1841 | G42: 0.1873 | H42: E1 | I42: 0.6844 | J42: 0.6979 | K42: E2 | L42: 0.1063 | M42: 0.1078 | N42: E3 | O42: 0.8064 | P42: 0.8155 | Q42: E4 | R42: 0.1828 | S42: 0.1869 | T42: E5 | U42: 0.683 | V42: 0.7011 | W42: E6 | X42: 0.1829 | Y42: 0.1856 | Z42: E7 | AA42: 0.6875 | AB42: 0.6974
A43: Média | F43: 0.18406 | G43: 0.18668 | I43: 0.68524 | J43: 0.69704 | L43: 0.10554 | M43: 0.1077 | O43: 0.80146 | P43: 0.81348 | R43: 0.18294 | S43: 0.18676 | U43: 0.68474 | V43: 0.69808 | X43: 0.1825 | Y43: 0.18572 | AA43: 0.6854 | AB43: 0.69704
...

Sheet DP2
AE2: Eletrodos de medição
A3: 1 | B3: -> | D3: E91 | E3: 1.2126 | F3: 1.3916 | G3: E92 | H3: 0 | I3: 0 | AE3: Eletrodos pares | AG3: Eletrodos ímpares
A4: 2 | B4: -> | C4: E1 | D4: I1 | E4: e | F4: E0 | G4: Terra | AE4: FREQ1 | AF4: FREQ2 | AG4: FREQ1 | AH4: FREQ2
A5: 3 | B5: -> | D5: E0 | J5: E2 | K5: 0.274 | L5: 0.2784 | M5: E3 | N5: 0.7782 | O5: 0.7908 | P5: E4 | Q5: 0.2755 | R5: 0.2791 | S5: E5 | T5: 0.7769 | U5: 0.7908 | V5: E6 | W5: 0.2756 | X5: 0.2779 | Y5: E7 | Z5: 0.7783 | AA5: 0.79 | AC5: Eletrodos de injeção | AD5: E1 | AE5: =_xlfn.STDEV.P(E5,K5,Q5,W5) -> 0.00073181661 | AF5: =_xlfn.STDEV.P(F5,L5,R5,X5) -> 0.00049216077 | AG5: =_xlfn.STDEV.P(H5,N5,T5,Z5) -> 0.00063770422 | AH5: =_xlfn.STDEV.P(I5,O5,U5,AA5) -> 0.00037712362
A6: 4 | B6: -> | C6: E2 | D6: I1 | E6: e | F6: E1 | G6: Terra
A7: 5 | B7: -> | D7: E0 | E7: 0.8631 | F7: 0.8778 | M7: E3 | N7: 0.3624 | O7: 0.3663 | P7: E4 | Q7: 0.8737 | R7: 0.8859 | S7: E5 | T7: 0.3634 | U7: 0.3683 | V7: E6 | W7: 0.8635 | X7: 0.8789 | Y7: E7 | Z7: 0.3633 | AA7: 0.3677 | AD7: E2 | AE7: =_xlfn.STDEV.P(E7,K7,Q7,W7) -> 0.0049053259 | AF7: =_xlfn.STDEV.P(F7,L7,R7,X7) -> 0.0035873234 | AG7: =_xlfn.STDEV.P(H7,N7,T7,Z7) -> 0.00044969125 | AH7: =_xlfn.STDEV.P(I7,O7,U7,AA7) -> 0.00083798701
A8: 6 | B8: -> | C8: E3 | D8: I1 | E8: e | F8: E2 | G8: Terra
A9: 7 | B9: -> | D9: E0 | E9: 0.1859 | F9: 0.1864 | G9: E1 | H9: 0.6855 | I9: 0.6964 | P9: E4 | Q9: 0.1832 | R9: 0.1876 | S9: E5 | T9: 0.6844 | U9: 0.6963 | V9: E6 | W9: 0.1824 | X9: 0.186 | Y9: E7 | Z9: 0.6877 | AA9: 0.6981 | AD9: E3 | AE9: =_xlfn.STDEV.P(E9,K9,Q9,W9) -> 0.0014974052 | AF9: =_xlfn.STDEV.P(F9,L9,R9,X9) -> 0.00067986927 | AG9: =_xlfn.STDEV.P(H9,N9,T9,Z9) -> 0.001371941 | AH9: =_xlfn.STDEV.P(I9,O9,U9,AA9) -> 0.00082596745
A10: 8 | B10: -> | C10: E4 | D10: I1 | E10: e | F10: E3 | G10: Terra
A11: 9 | B11: -> | D11: E0 | E11: 0.7257 | F11: 0.7372 | G11: E1 | H11: 0.2196 | I11: 0.2253 | J11: E2 | K11: 0.7223 | L11: 0.7373 | S11: E5 | T11: 0.2198 | U11: 0.2271 | V11: E6 | W11: 0.7229 | X11: 0.7355 | Y11: E7 | Z11: 0.2232 | AA11: 0.2241 | AD11: E4 | AE11: =_xlfn.STDEV.P(E11,K11,Q11,W11) -> 0.0014817407 | AF11: =_xlfn.STDEV.P(F11,L11,R11,X11) -> 0.00082596745 | AG11: =_xlfn.STDEV.P(H11,N11,T11,Z11) -> 0.0016519349 | AH11: =_xlfn.STDEV.P(I11,O11,U11,AA11) -> 0.0012328828
A12: 10 | B12: -> | C12: E5 | D12: I1 | E12: e | F12: E4 | G12: Terra
A13: 11 | B13: -> | D13: E0 | E13: 0.2422 | F13: 0.2455 | G13: E1 | H13: 0.7427 | I13: 0.7517 | J13: E2 | K13: 0.2359 | L13: 0.2428 | M13: E3 | N13: 0.7393 | O13: 0.7522 | V13: E6 | W13: 0.2392 | X13: 0.2423 | Y13: E7 | Z13: 0.7316 | AA13: 0.7483 | AD13: E5 | AE13: =_xlfn.STDEV.P(E13,K13,Q13,W13) -> 0.0025729361 | AF13: =_xlfn.STDEV.P(F13,L13,R13,X13) -> 0.0014055446 | AG13: =_xlfn.STDEV.P(H13,N13,T13,Z13) -> 0.004643514 | AH13: =_xlfn.STDEV.P(I13,O13,U13,AA13) -> 0.0017326922
A14: 12 | B14: -> | C14: E6 | D14: I1 | E14: e | F14: E5 | G14: Terra
A15: 13 | B15: -> | D15: E0 | E15: 0.8412 | F15: 0.856 | G15: E1 | H15: 0.3381 | I15: 0.3434 | J15: E2 | K15: 0.8373 | L15: 0.8536 | M15: E3 | N15: 0.3394 | O15: 0.3432 | P15: E4 | Q15: 0.8418 | R15: 0.8516 | Y15: E7 | Z15: 0.3389 | AA15: 0.3439 | AD15: E6 | AE15: =_xlfn.STDEV.P(E15,K15,Q15,W15) -> 0.0019949937 | AF15: =_xlfn.STDEV.P(F15,L15,R15,X15) -> 0.001798765 | AG15: =_xlfn.STDEV.P(H15,N15,T15,Z15) -> 0.00053541261 | AH15: =_xlfn.STDEV.P(I15,O15,U15,AA15) -> 0.00029439203
A16: 14 | B16: -> | C16: E7 | D16: I1 | E16: e | F16: E6 | G16: Terra
A17: 15 | B17: -> | D17: E0 | E17: 0.1759 | F17: 0.1794 | G17: E1 | H17: 0.6789 | I17: 0.6895 | J17: E2 | K17: 0.1753 | L17: 0.1782 | M17: E3 | N17: 0.679 | O17: 0.6905 | P17: E4 | Q17: 0.1709 | R17: 0.1755 | S17: E5 | T17: 0.6799 | U17: 0.6894 | AD17: E7 | AE17: =_xlfn.STDEV.P(E17,K17,Q17,W17) -> 0.0022291005 | AF17: =_xlfn.STDEV.P(F17,L17,R17,X17) -> 0.0016309506 | AG17: =_xlfn.STDEV.P(H17,N17,T17,Z17) -> 0.00044969125 | AH17: =_xlfn.STDEV.P(I17,O17,U17,AA17) -> 0.00049665548
A18: 16 | B18: -> | C18: E0 | D18: I1 | E18: e | F18: E7 | G18: Terra
A19: 17 | B19: -> | G19: E1 | H19: 0.4472 | I19: 0.4548 | J19: E2 | K19: 0.9213 | L19: 0.9383 | M19: E3 | N19: 0.4477 | O19: 0.4552 | P19: E4 | Q19: 0.9245 | R19: 0.9429 | S19: E5 | T19: 0.4476 | U19: 0.4556 | V19: E6 | W19: 0.9232 | X19: 0.9391 | AD19: E8 | AE19: =_xlfn.STDEV.P(E19,K19,Q19,W19) -> 0.0013140269 | AF19: =_xlfn.STDEV.P(F19,L19,R19,X19) -> 0.0020066556 | AG19: =_xlfn.STDEV.P(H19,N19,T19,Z19) -> 0.00021602469 | AH19: =_xlfn.STDEV.P(I19,O19,U19,AA19) -> 0.00032659863
